2014-02-10 16:15:28+0800 [scrapy] INFO: Scrapy 0.22.0 started (bot: taobao)
2014-02-10 16:15:28+0800 [scrapy] INFO: Optional features available: ssl, http11
2014-02-10 16:15:28+0800 [scrapy] INFO: Overridden settings: {'NEWSPIDER_MODULE': 'taobao.spiders', 'SPIDER_MODULES': ['taobao.spiders'], 'BOT_NAME': 'taobao'}
2014-02-10 16:15:28+0800 [scrapy] INFO: Enabled extensions: LogStats, TelnetConsole, CloseSpider, WebService, CoreStats, SpiderState
2014-02-10 16:15:28+0800 [scrapy] INFO: Enabled downloader middlewares: HttpAuthMiddleware, DownloadTimeoutMiddleware, UserAgentMiddleware, RetryMiddleware, DefaultHeadersMiddleware, MetaRefreshMiddleware, HttpCompressionMiddleware, RedirectMiddleware, CookiesMiddleware, ChunkedTransferMiddleware, DownloaderStats
2014-02-10 16:15:28+0800 [scrapy] INFO: Enabled spider middlewares: HttpErrorMiddleware, OffsiteMiddleware, RefererMiddleware, UrlLengthMiddleware, DepthMiddleware
2014-02-10 16:15:28+0800 [scrapy] INFO: Enabled item pipelines: SellerPipeline
2014-02-10 16:15:28+0800 [taobao] INFO: Spider opened
2014-02-10 16:15:28+0800 [taobao] INFO: Crawled 0 pages (at 0 pages/min), scraped 0 items (at 0 items/min)
2014-02-10 16:15:28+0800 [scrapy] DEBUG: Telnet console listening on 0.0.0.0:6023
2014-02-10 16:15:28+0800 [scrapy] DEBUG: Web service listening on 0.0.0.0:6080
2014-02-10 16:15:29+0800 [taobao] DEBUG: Crawled (200) <GET http://www.taobao.com/market/3c/phone_index.php> (referer: None)
2014-02-10 16:15:29+0800 [taobao] DEBUG: Crawled (200) <GET http://spu.taobao.com/spu/3c/detail.htm?spm=1020.2.4.1.312R7A&cat=1512&spuid=229361412#content> (referer: http://www.taobao.com/market/3c/phone_index.php)
No handlers could be found for logger "peewee"
2014-02-10 16:15:29+0800 [taobao] ERROR: Error processing {'flag': 'Seller',
	 'name': u'\u65e0\u9645\u9ea6\u7530\u901a\u8baf',
	 'positiveFeedbackRate': 98.97,
	 'reputScore': 2001,
	 'sellerId': 376799512,
	 'shopDesc': [4.8, 4.8, 4.8]}
	Traceback (most recent call last):
	  File "/usr/local/lib/python2.7/dist-packages/scrapy/middleware.py", line 62, in _process_chain
	    return process_chain(self.methods[methodname], obj, *args)
	  File "/usr/local/lib/python2.7/dist-packages/scrapy/utils/defer.py", line 65, in process_chain
	    d.callback(input)
	  File "/usr/local/lib/python2.7/dist-packages/twisted/internet/defer.py", line 382, in callback
	    self._startRunCallbacks(result)
	  File "/usr/local/lib/python2.7/dist-packages/twisted/internet/defer.py", line 490, in _startRunCallbacks
	    self._runCallbacks()
	--- <exception caught here> ---
	  File "/usr/local/lib/python2.7/dist-packages/twisted/internet/defer.py", line 577, in _runCallbacks
	    current.result = callback(current.result, *args, **kw)
	  File "/home/zq/Project/taobao/taobao/pipelines.py", line 22, in process_item
	    seller.save()
	  File "/usr/local/lib/python2.7/dist-packages/peewee.py", line 2837, in save
	    ret_pk = self.insert(**field_dict).execute()
	  File "/usr/local/lib/python2.7/dist-packages/peewee.py", line 2000, in execute
	    return self.database.last_insert_id(self._execute(), self.model_class)
	  File "/usr/local/lib/python2.7/dist-packages/peewee.py", line 1671, in _execute
	    return self.database.execute_sql(sql, params, self.require_commit)
	  File "/usr/local/lib/python2.7/dist-packages/peewee.py", line 2162, in execute_sql
	    self.commit()
	  File "/usr/local/lib/python2.7/dist-packages/peewee.py", line 2036, in __exit__
	    reraise(new_type, new_type(*exc_value.args), traceback)
	  File "/usr/local/lib/python2.7/dist-packages/peewee.py", line 2153, in execute_sql
	    res = cursor.execute(sql, params or ())
	peewee.IntegrityError: null value in column "commId" violates not-null constraint
	
	
2014-02-10 16:15:29+0800 [taobao] ERROR: Error processing {'flag': 'Seller',
	 'name': u'\u4e09\u4f1f\u7d22\u7231\u79d1\u6280',
	 'positiveFeedbackRate': 99.47,
	 'reputScore': 20001,
	 'sellerId': 380624657,
	 'shopDesc': [4.8, 4.8, 4.8]}
	Traceback (most recent call last):
	  File "/usr/local/lib/python2.7/dist-packages/scrapy/middleware.py", line 62, in _process_chain
	    return process_chain(self.methods[methodname], obj, *args)
	  File "/usr/local/lib/python2.7/dist-packages/scrapy/utils/defer.py", line 65, in process_chain
	    d.callback(input)
	  File "/usr/local/lib/python2.7/dist-packages/twisted/internet/defer.py", line 382, in callback
	    self._startRunCallbacks(result)
	  File "/usr/local/lib/python2.7/dist-packages/twisted/internet/defer.py", line 490, in _startRunCallbacks
	    self._runCallbacks()
	--- <exception caught here> ---
	  File "/usr/local/lib/python2.7/dist-packages/twisted/internet/defer.py", line 577, in _runCallbacks
	    current.result = callback(current.result, *args, **kw)
	  File "/home/zq/Project/taobao/taobao/pipelines.py", line 22, in process_item
	    seller.save()
	  File "/usr/local/lib/python2.7/dist-packages/peewee.py", line 2837, in save
	    ret_pk = self.insert(**field_dict).execute()
	  File "/usr/local/lib/python2.7/dist-packages/peewee.py", line 2000, in execute
	    return self.database.last_insert_id(self._execute(), self.model_class)
	  File "/usr/local/lib/python2.7/dist-packages/peewee.py", line 1671, in _execute
	    return self.database.execute_sql(sql, params, self.require_commit)
	  File "/usr/local/lib/python2.7/dist-packages/peewee.py", line 2162, in execute_sql
	    self.commit()
	  File "/usr/local/lib/python2.7/dist-packages/peewee.py", line 2036, in __exit__
	    reraise(new_type, new_type(*exc_value.args), traceback)
	  File "/usr/local/lib/python2.7/dist-packages/peewee.py", line 2153, in execute_sql
	    res = cursor.execute(sql, params or ())
	peewee.InternalError: current transaction is aborted, commands ignored until end of transaction block
	
	
2014-02-10 16:15:29+0800 [taobao] ERROR: Error processing {'flag': 'Seller',
	 'name': u'\u6700\u4f4e\u6700\u8bda\u4fe1',
	 'positiveFeedbackRate': 99.86,
	 'reputScore': 100001,
	 'sellerId': 12573474,
	 'shopDesc': [4.8, 4.8, 4.8]}
	Traceback (most recent call last):
	  File "/usr/local/lib/python2.7/dist-packages/scrapy/middleware.py", line 62, in _process_chain
	    return process_chain(self.methods[methodname], obj, *args)
	  File "/usr/local/lib/python2.7/dist-packages/scrapy/utils/defer.py", line 65, in process_chain
	    d.callback(input)
	  File "/usr/local/lib/python2.7/dist-packages/twisted/internet/defer.py", line 382, in callback
	    self._startRunCallbacks(result)
	  File "/usr/local/lib/python2.7/dist-packages/twisted/internet/defer.py", line 490, in _startRunCallbacks
	    self._runCallbacks()
	--- <exception caught here> ---
	  File "/usr/local/lib/python2.7/dist-packages/twisted/internet/defer.py", line 577, in _runCallbacks
	    current.result = callback(current.result, *args, **kw)
	  File "/home/zq/Project/taobao/taobao/pipelines.py", line 22, in process_item
	    seller.save()
	  File "/usr/local/lib/python2.7/dist-packages/peewee.py", line 2837, in save
	    ret_pk = self.insert(**field_dict).execute()
	  File "/usr/local/lib/python2.7/dist-packages/peewee.py", line 2000, in execute
	    return self.database.last_insert_id(self._execute(), self.model_class)
	  File "/usr/local/lib/python2.7/dist-packages/peewee.py", line 1671, in _execute
	    return self.database.execute_sql(sql, params, self.require_commit)
	  File "/usr/local/lib/python2.7/dist-packages/peewee.py", line 2162, in execute_sql
	    self.commit()
	  File "/usr/local/lib/python2.7/dist-packages/peewee.py", line 2036, in __exit__
	    reraise(new_type, new_type(*exc_value.args), traceback)
	  File "/usr/local/lib/python2.7/dist-packages/peewee.py", line 2153, in execute_sql
	    res = cursor.execute(sql, params or ())
	peewee.InternalError: current transaction is aborted, commands ignored until end of transaction block
	
	
2014-02-10 16:15:29+0800 [taobao] ERROR: Error processing {'flag': 'Seller',
	 'name': u'\u975e\u5e38\u624b\u673a',
	 'positiveFeedbackRate': 99.6,
	 'reputScore': 500001,
	 'sellerId': 853982,
	 'shopDesc': [4.7, 4.7, 4.7]}
	Traceback (most recent call last):
	  File "/usr/local/lib/python2.7/dist-packages/scrapy/middleware.py", line 62, in _process_chain
	    return process_chain(self.methods[methodname], obj, *args)
	  File "/usr/local/lib/python2.7/dist-packages/scrapy/utils/defer.py", line 65, in process_chain
	    d.callback(input)
	  File "/usr/local/lib/python2.7/dist-packages/twisted/internet/defer.py", line 382, in callback
	    self._startRunCallbacks(result)
	  File "/usr/local/lib/python2.7/dist-packages/twisted/internet/defer.py", line 490, in _startRunCallbacks
	    self._runCallbacks()
	--- <exception caught here> ---
	  File "/usr/local/lib/python2.7/dist-packages/twisted/internet/defer.py", line 577, in _runCallbacks
	    current.result = callback(current.result, *args, **kw)
	  File "/home/zq/Project/taobao/taobao/pipelines.py", line 22, in process_item
	    seller.save()
	  File "/usr/local/lib/python2.7/dist-packages/peewee.py", line 2837, in save
	    ret_pk = self.insert(**field_dict).execute()
	  File "/usr/local/lib/python2.7/dist-packages/peewee.py", line 2000, in execute
	    return self.database.last_insert_id(self._execute(), self.model_class)
	  File "/usr/local/lib/python2.7/dist-packages/peewee.py", line 1671, in _execute
	    return self.database.execute_sql(sql, params, self.require_commit)
	  File "/usr/local/lib/python2.7/dist-packages/peewee.py", line 2162, in execute_sql
	    self.commit()
	  File "/usr/local/lib/python2.7/dist-packages/peewee.py", line 2036, in __exit__
	    reraise(new_type, new_type(*exc_value.args), traceback)
	  File "/usr/local/lib/python2.7/dist-packages/peewee.py", line 2153, in execute_sql
	    res = cursor.execute(sql, params or ())
	peewee.InternalError: current transaction is aborted, commands ignored until end of transaction block
	
	
2014-02-10 16:15:29+0800 [taobao] ERROR: Error processing {'flag': 'Seller',
	 'name': u'\u65b0\u592a\u6570\u7801\u901a\u8baf',
	 'positiveFeedbackRate': 99.19,
	 'reputScore': 50001,
	 'sellerId': 183262695,
	 'shopDesc': [4.7, 4.6, 4.6]}
	Traceback (most recent call last):
	  File "/usr/local/lib/python2.7/dist-packages/scrapy/middleware.py", line 62, in _process_chain
	    return process_chain(self.methods[methodname], obj, *args)
	  File "/usr/local/lib/python2.7/dist-packages/scrapy/utils/defer.py", line 65, in process_chain
	    d.callback(input)
	  File "/usr/local/lib/python2.7/dist-packages/twisted/internet/defer.py", line 382, in callback
	    self._startRunCallbacks(result)
	  File "/usr/local/lib/python2.7/dist-packages/twisted/internet/defer.py", line 490, in _startRunCallbacks
	    self._runCallbacks()
	--- <exception caught here> ---
	  File "/usr/local/lib/python2.7/dist-packages/twisted/internet/defer.py", line 577, in _runCallbacks
	    current.result = callback(current.result, *args, **kw)
	  File "/home/zq/Project/taobao/taobao/pipelines.py", line 22, in process_item
	    seller.save()
	  File "/usr/local/lib/python2.7/dist-packages/peewee.py", line 2837, in save
	    ret_pk = self.insert(**field_dict).execute()
	  File "/usr/local/lib/python2.7/dist-packages/peewee.py", line 2000, in execute
	    return self.database.last_insert_id(self._execute(), self.model_class)
	  File "/usr/local/lib/python2.7/dist-packages/peewee.py", line 1671, in _execute
	    return self.database.execute_sql(sql, params, self.require_commit)
	  File "/usr/local/lib/python2.7/dist-packages/peewee.py", line 2162, in execute_sql
	    self.commit()
	  File "/usr/local/lib/python2.7/dist-packages/peewee.py", line 2036, in __exit__
	    reraise(new_type, new_type(*exc_value.args), traceback)
	  File "/usr/local/lib/python2.7/dist-packages/peewee.py", line 2153, in execute_sql
	    res = cursor.execute(sql, params or ())
	peewee.InternalError: current transaction is aborted, commands ignored until end of transaction block
	
	
2014-02-10 16:15:29+0800 [taobao] ERROR: Error processing {'flag': 'Seller',
	 'name': u'jj.shen',
	 'positiveFeedbackRate': 99.79,
	 'reputScore': 20001,
	 'sellerId': 20543624,
	 'shopDesc': [4.8, 4.8, 4.8]}
	Traceback (most recent call last):
	  File "/usr/local/lib/python2.7/dist-packages/scrapy/middleware.py", line 62, in _process_chain
	    return process_chain(self.methods[methodname], obj, *args)
	  File "/usr/local/lib/python2.7/dist-packages/scrapy/utils/defer.py", line 65, in process_chain
	    d.callback(input)
	  File "/usr/local/lib/python2.7/dist-packages/twisted/internet/defer.py", line 382, in callback
	    self._startRunCallbacks(result)
	  File "/usr/local/lib/python2.7/dist-packages/twisted/internet/defer.py", line 490, in _startRunCallbacks
	    self._runCallbacks()
	--- <exception caught here> ---
	  File "/usr/local/lib/python2.7/dist-packages/twisted/internet/defer.py", line 577, in _runCallbacks
	    current.result = callback(current.result, *args, **kw)
	  File "/home/zq/Project/taobao/taobao/pipelines.py", line 22, in process_item
	    seller.save()
	  File "/usr/local/lib/python2.7/dist-packages/peewee.py", line 2837, in save
	    ret_pk = self.insert(**field_dict).execute()
	  File "/usr/local/lib/python2.7/dist-packages/peewee.py", line 2000, in execute
	    return self.database.last_insert_id(self._execute(), self.model_class)
	  File "/usr/local/lib/python2.7/dist-packages/peewee.py", line 1671, in _execute
	    return self.database.execute_sql(sql, params, self.require_commit)
	  File "/usr/local/lib/python2.7/dist-packages/peewee.py", line 2162, in execute_sql
	    self.commit()
	  File "/usr/local/lib/python2.7/dist-packages/peewee.py", line 2036, in __exit__
	    reraise(new_type, new_type(*exc_value.args), traceback)
	  File "/usr/local/lib/python2.7/dist-packages/peewee.py", line 2153, in execute_sql
	    res = cursor.execute(sql, params or ())
	peewee.InternalError: current transaction is aborted, commands ignored until end of transaction block
	
	
2014-02-10 16:15:29+0800 [taobao] ERROR: Error processing {'flag': 'Seller',
	 'name': u'\u53ea\u6709\u4e3a\u4f60123456',
	 'positiveFeedbackRate': 99.92,
	 'reputScore': 2001,
	 'sellerId': 118130847,
	 'shopDesc': [4.9, 4.9, 4.9]}
	Traceback (most recent call last):
	  File "/usr/local/lib/python2.7/dist-packages/scrapy/middleware.py", line 62, in _process_chain
	    return process_chain(self.methods[methodname], obj, *args)
	  File "/usr/local/lib/python2.7/dist-packages/scrapy/utils/defer.py", line 65, in process_chain
	    d.callback(input)
	  File "/usr/local/lib/python2.7/dist-packages/twisted/internet/defer.py", line 382, in callback
	    self._startRunCallbacks(result)
	  File "/usr/local/lib/python2.7/dist-packages/twisted/internet/defer.py", line 490, in _startRunCallbacks
	    self._runCallbacks()
	--- <exception caught here> ---
	  File "/usr/local/lib/python2.7/dist-packages/twisted/internet/defer.py", line 577, in _runCallbacks
	    current.result = callback(current.result, *args, **kw)
	  File "/home/zq/Project/taobao/taobao/pipelines.py", line 22, in process_item
	    seller.save()
	  File "/usr/local/lib/python2.7/dist-packages/peewee.py", line 2837, in save
	    ret_pk = self.insert(**field_dict).execute()
	  File "/usr/local/lib/python2.7/dist-packages/peewee.py", line 2000, in execute
	    return self.database.last_insert_id(self._execute(), self.model_class)
	  File "/usr/local/lib/python2.7/dist-packages/peewee.py", line 1671, in _execute
	    return self.database.execute_sql(sql, params, self.require_commit)
	  File "/usr/local/lib/python2.7/dist-packages/peewee.py", line 2162, in execute_sql
	    self.commit()
	  File "/usr/local/lib/python2.7/dist-packages/peewee.py", line 2036, in __exit__
	    reraise(new_type, new_type(*exc_value.args), traceback)
	  File "/usr/local/lib/python2.7/dist-packages/peewee.py", line 2153, in execute_sql
	    res = cursor.execute(sql, params or ())
	peewee.InternalError: current transaction is aborted, commands ignored until end of transaction block
	
	
2014-02-10 16:15:29+0800 [taobao] ERROR: Error processing {'flag': 'Seller',
	 'name': u'\u9038\u67ab66',
	 'positiveFeedbackRate': 99.63,
	 'reputScore': 10001,
	 'sellerId': 37830682,
	 'shopDesc': [4.8, 4.8, 4.8]}
	Traceback (most recent call last):
	  File "/usr/local/lib/python2.7/dist-packages/scrapy/middleware.py", line 62, in _process_chain
	    return process_chain(self.methods[methodname], obj, *args)
	  File "/usr/local/lib/python2.7/dist-packages/scrapy/utils/defer.py", line 65, in process_chain
	    d.callback(input)
	  File "/usr/local/lib/python2.7/dist-packages/twisted/internet/defer.py", line 382, in callback
	    self._startRunCallbacks(result)
	  File "/usr/local/lib/python2.7/dist-packages/twisted/internet/defer.py", line 490, in _startRunCallbacks
	    self._runCallbacks()
	--- <exception caught here> ---
	  File "/usr/local/lib/python2.7/dist-packages/twisted/internet/defer.py", line 577, in _runCallbacks
	    current.result = callback(current.result, *args, **kw)
	  File "/home/zq/Project/taobao/taobao/pipelines.py", line 22, in process_item
	    seller.save()
	  File "/usr/local/lib/python2.7/dist-packages/peewee.py", line 2837, in save
	    ret_pk = self.insert(**field_dict).execute()
	  File "/usr/local/lib/python2.7/dist-packages/peewee.py", line 2000, in execute
	    return self.database.last_insert_id(self._execute(), self.model_class)
	  File "/usr/local/lib/python2.7/dist-packages/peewee.py", line 1671, in _execute
	    return self.database.execute_sql(sql, params, self.require_commit)
	  File "/usr/local/lib/python2.7/dist-packages/peewee.py", line 2162, in execute_sql
	    self.commit()
	  File "/usr/local/lib/python2.7/dist-packages/peewee.py", line 2036, in __exit__
	    reraise(new_type, new_type(*exc_value.args), traceback)
	  File "/usr/local/lib/python2.7/dist-packages/peewee.py", line 2153, in execute_sql
	    res = cursor.execute(sql, params or ())
	peewee.InternalError: current transaction is aborted, commands ignored until end of transaction block
	
	
2014-02-10 16:15:29+0800 [taobao] ERROR: Error processing {'flag': 'Seller',
	 'name': u'gamenan',
	 'positiveFeedbackRate': 99.8,
	 'reputScore': 20001,
	 'sellerId': 196118321,
	 'shopDesc': [4.8, 4.8, 4.8]}
	Traceback (most recent call last):
	  File "/usr/local/lib/python2.7/dist-packages/scrapy/middleware.py", line 62, in _process_chain
	    return process_chain(self.methods[methodname], obj, *args)
	  File "/usr/local/lib/python2.7/dist-packages/scrapy/utils/defer.py", line 65, in process_chain
	    d.callback(input)
	  File "/usr/local/lib/python2.7/dist-packages/twisted/internet/defer.py", line 382, in callback
	    self._startRunCallbacks(result)
	  File "/usr/local/lib/python2.7/dist-packages/twisted/internet/defer.py", line 490, in _startRunCallbacks
	    self._runCallbacks()
	--- <exception caught here> ---
	  File "/usr/local/lib/python2.7/dist-packages/twisted/internet/defer.py", line 577, in _runCallbacks
	    current.result = callback(current.result, *args, **kw)
	  File "/home/zq/Project/taobao/taobao/pipelines.py", line 22, in process_item
	    seller.save()
	  File "/usr/local/lib/python2.7/dist-packages/peewee.py", line 2837, in save
	    ret_pk = self.insert(**field_dict).execute()
	  File "/usr/local/lib/python2.7/dist-packages/peewee.py", line 2000, in execute
	    return self.database.last_insert_id(self._execute(), self.model_class)
	  File "/usr/local/lib/python2.7/dist-packages/peewee.py", line 1671, in _execute
	    return self.database.execute_sql(sql, params, self.require_commit)
	  File "/usr/local/lib/python2.7/dist-packages/peewee.py", line 2162, in execute_sql
	    self.commit()
	  File "/usr/local/lib/python2.7/dist-packages/peewee.py", line 2036, in __exit__
	    reraise(new_type, new_type(*exc_value.args), traceback)
	  File "/usr/local/lib/python2.7/dist-packages/peewee.py", line 2153, in execute_sql
	    res = cursor.execute(sql, params or ())
	peewee.InternalError: current transaction is aborted, commands ignored until end of transaction block
	
	
2014-02-10 16:15:29+0800 [taobao] ERROR: Error processing {'flag': 'Seller',
	 'name': u'yulicun888',
	 'positiveFeedbackRate': 99.42,
	 'reputScore': 20001,
	 'sellerId': 141757951,
	 'shopDesc': [4.8, 4.8, 4.8]}
	Traceback (most recent call last):
	  File "/usr/local/lib/python2.7/dist-packages/scrapy/middleware.py", line 62, in _process_chain
	    return process_chain(self.methods[methodname], obj, *args)
	  File "/usr/local/lib/python2.7/dist-packages/scrapy/utils/defer.py", line 65, in process_chain
	    d.callback(input)
	  File "/usr/local/lib/python2.7/dist-packages/twisted/internet/defer.py", line 382, in callback
	    self._startRunCallbacks(result)
	  File "/usr/local/lib/python2.7/dist-packages/twisted/internet/defer.py", line 490, in _startRunCallbacks
	    self._runCallbacks()
	--- <exception caught here> ---
	  File "/usr/local/lib/python2.7/dist-packages/twisted/internet/defer.py", line 577, in _runCallbacks
	    current.result = callback(current.result, *args, **kw)
	  File "/home/zq/Project/taobao/taobao/pipelines.py", line 22, in process_item
	    seller.save()
	  File "/usr/local/lib/python2.7/dist-packages/peewee.py", line 2837, in save
	    ret_pk = self.insert(**field_dict).execute()
	  File "/usr/local/lib/python2.7/dist-packages/peewee.py", line 2000, in execute
	    return self.database.last_insert_id(self._execute(), self.model_class)
	  File "/usr/local/lib/python2.7/dist-packages/peewee.py", line 1671, in _execute
	    return self.database.execute_sql(sql, params, self.require_commit)
	  File "/usr/local/lib/python2.7/dist-packages/peewee.py", line 2162, in execute_sql
	    self.commit()
	  File "/usr/local/lib/python2.7/dist-packages/peewee.py", line 2036, in __exit__
	    reraise(new_type, new_type(*exc_value.args), traceback)
	  File "/usr/local/lib/python2.7/dist-packages/peewee.py", line 2153, in execute_sql
	    res = cursor.execute(sql, params or ())
	peewee.InternalError: current transaction is aborted, commands ignored until end of transaction block
	
	
2014-02-10 16:15:29+0800 [taobao] ERROR: Error processing {'flag': 'Seller',
	 'name': u'\u8349\u6837\u5e74\u534e37',
	 'positiveFeedbackRate': 99.67,
	 'reputScore': 2001,
	 'sellerId': 688690474,
	 'shopDesc': [4.9, 4.9, 4.9]}
	Traceback (most recent call last):
	  File "/usr/local/lib/python2.7/dist-packages/scrapy/middleware.py", line 62, in _process_chain
	    return process_chain(self.methods[methodname], obj, *args)
	  File "/usr/local/lib/python2.7/dist-packages/scrapy/utils/defer.py", line 65, in process_chain
	    d.callback(input)
	  File "/usr/local/lib/python2.7/dist-packages/twisted/internet/defer.py", line 382, in callback
	    self._startRunCallbacks(result)
	  File "/usr/local/lib/python2.7/dist-packages/twisted/internet/defer.py", line 490, in _startRunCallbacks
	    self._runCallbacks()
	--- <exception caught here> ---
	  File "/usr/local/lib/python2.7/dist-packages/twisted/internet/defer.py", line 577, in _runCallbacks
	    current.result = callback(current.result, *args, **kw)
	  File "/home/zq/Project/taobao/taobao/pipelines.py", line 22, in process_item
	    seller.save()
	  File "/usr/local/lib/python2.7/dist-packages/peewee.py", line 2837, in save
	    ret_pk = self.insert(**field_dict).execute()
	  File "/usr/local/lib/python2.7/dist-packages/peewee.py", line 2000, in execute
	    return self.database.last_insert_id(self._execute(), self.model_class)
	  File "/usr/local/lib/python2.7/dist-packages/peewee.py", line 1671, in _execute
	    return self.database.execute_sql(sql, params, self.require_commit)
	  File "/usr/local/lib/python2.7/dist-packages/peewee.py", line 2162, in execute_sql
	    self.commit()
	  File "/usr/local/lib/python2.7/dist-packages/peewee.py", line 2036, in __exit__
	    reraise(new_type, new_type(*exc_value.args), traceback)
	  File "/usr/local/lib/python2.7/dist-packages/peewee.py", line 2153, in execute_sql
	    res = cursor.execute(sql, params or ())
	peewee.InternalError: current transaction is aborted, commands ignored until end of transaction block
	
	
2014-02-10 16:15:29+0800 [taobao] ERROR: Error processing {'flag': 'Seller',
	 'name': u'\u84dd\u6d77\u5c0fc',
	 'positiveFeedbackRate': 0.0,
	 'reputScore': 1001,
	 'sellerId': 477135813,
	 'shopDesc': [4.8, 4.8, 4.8]}
	Traceback (most recent call last):
	  File "/usr/local/lib/python2.7/dist-packages/scrapy/middleware.py", line 62, in _process_chain
	    return process_chain(self.methods[methodname], obj, *args)
	  File "/usr/local/lib/python2.7/dist-packages/scrapy/utils/defer.py", line 65, in process_chain
	    d.callback(input)
	  File "/usr/local/lib/python2.7/dist-packages/twisted/internet/defer.py", line 382, in callback
	    self._startRunCallbacks(result)
	  File "/usr/local/lib/python2.7/dist-packages/twisted/internet/defer.py", line 490, in _startRunCallbacks
	    self._runCallbacks()
	--- <exception caught here> ---
	  File "/usr/local/lib/python2.7/dist-packages/twisted/internet/defer.py", line 577, in _runCallbacks
	    current.result = callback(current.result, *args, **kw)
	  File "/home/zq/Project/taobao/taobao/pipelines.py", line 22, in process_item
	    seller.save()
	  File "/usr/local/lib/python2.7/dist-packages/peewee.py", line 2837, in save
	    ret_pk = self.insert(**field_dict).execute()
	  File "/usr/local/lib/python2.7/dist-packages/peewee.py", line 2000, in execute
	    return self.database.last_insert_id(self._execute(), self.model_class)
	  File "/usr/local/lib/python2.7/dist-packages/peewee.py", line 1671, in _execute
	    return self.database.execute_sql(sql, params, self.require_commit)
	  File "/usr/local/lib/python2.7/dist-packages/peewee.py", line 2162, in execute_sql
	    self.commit()
	  File "/usr/local/lib/python2.7/dist-packages/peewee.py", line 2036, in __exit__
	    reraise(new_type, new_type(*exc_value.args), traceback)
	  File "/usr/local/lib/python2.7/dist-packages/peewee.py", line 2153, in execute_sql
	    res = cursor.execute(sql, params or ())
	peewee.InternalError: current transaction is aborted, commands ignored until end of transaction block
	
	
2014-02-10 16:15:29+0800 [taobao] ERROR: Error processing {'flag': 'Seller',
	 'name': u'\u542f\u6cf0\u6570\u7801',
	 'positiveFeedbackRate': 99.1,
	 'reputScore': 50001,
	 'sellerId': 387784786,
	 'shopDesc': [4.8, 4.8, 4.8]}
	Traceback (most recent call last):
	  File "/usr/local/lib/python2.7/dist-packages/scrapy/middleware.py", line 62, in _process_chain
	    return process_chain(self.methods[methodname], obj, *args)
	  File "/usr/local/lib/python2.7/dist-packages/scrapy/utils/defer.py", line 65, in process_chain
	    d.callback(input)
	  File "/usr/local/lib/python2.7/dist-packages/twisted/internet/defer.py", line 382, in callback
	    self._startRunCallbacks(result)
	  File "/usr/local/lib/python2.7/dist-packages/twisted/internet/defer.py", line 490, in _startRunCallbacks
	    self._runCallbacks()
	--- <exception caught here> ---
	  File "/usr/local/lib/python2.7/dist-packages/twisted/internet/defer.py", line 577, in _runCallbacks
	    current.result = callback(current.result, *args, **kw)
	  File "/home/zq/Project/taobao/taobao/pipelines.py", line 22, in process_item
	    seller.save()
	  File "/usr/local/lib/python2.7/dist-packages/peewee.py", line 2837, in save
	    ret_pk = self.insert(**field_dict).execute()
	  File "/usr/local/lib/python2.7/dist-packages/peewee.py", line 2000, in execute
	    return self.database.last_insert_id(self._execute(), self.model_class)
	  File "/usr/local/lib/python2.7/dist-packages/peewee.py", line 1671, in _execute
	    return self.database.execute_sql(sql, params, self.require_commit)
	  File "/usr/local/lib/python2.7/dist-packages/peewee.py", line 2162, in execute_sql
	    self.commit()
	  File "/usr/local/lib/python2.7/dist-packages/peewee.py", line 2036, in __exit__
	    reraise(new_type, new_type(*exc_value.args), traceback)
	  File "/usr/local/lib/python2.7/dist-packages/peewee.py", line 2153, in execute_sql
	    res = cursor.execute(sql, params or ())
	peewee.InternalError: current transaction is aborted, commands ignored until end of transaction block
	
	
2014-02-10 16:15:29+0800 [taobao] ERROR: Error processing {'flag': 'Seller',
	 'name': u'\u6dc5\u6c5f\u5546\u53f7',
	 'positiveFeedbackRate': 99.9,
	 'reputScore': 10001,
	 'sellerId': 280003475,
	 'shopDesc': [4.9, 4.8, 4.9]}
	Traceback (most recent call last):
	  File "/usr/local/lib/python2.7/dist-packages/scrapy/middleware.py", line 62, in _process_chain
	    return process_chain(self.methods[methodname], obj, *args)
	  File "/usr/local/lib/python2.7/dist-packages/scrapy/utils/defer.py", line 65, in process_chain
	    d.callback(input)
	  File "/usr/local/lib/python2.7/dist-packages/twisted/internet/defer.py", line 382, in callback
	    self._startRunCallbacks(result)
	  File "/usr/local/lib/python2.7/dist-packages/twisted/internet/defer.py", line 490, in _startRunCallbacks
	    self._runCallbacks()
	--- <exception caught here> ---
	  File "/usr/local/lib/python2.7/dist-packages/twisted/internet/defer.py", line 577, in _runCallbacks
	    current.result = callback(current.result, *args, **kw)
	  File "/home/zq/Project/taobao/taobao/pipelines.py", line 22, in process_item
	    seller.save()
	  File "/usr/local/lib/python2.7/dist-packages/peewee.py", line 2837, in save
	    ret_pk = self.insert(**field_dict).execute()
	  File "/usr/local/lib/python2.7/dist-packages/peewee.py", line 2000, in execute
	    return self.database.last_insert_id(self._execute(), self.model_class)
	  File "/usr/local/lib/python2.7/dist-packages/peewee.py", line 1671, in _execute
	    return self.database.execute_sql(sql, params, self.require_commit)
	  File "/usr/local/lib/python2.7/dist-packages/peewee.py", line 2162, in execute_sql
	    self.commit()
	  File "/usr/local/lib/python2.7/dist-packages/peewee.py", line 2036, in __exit__
	    reraise(new_type, new_type(*exc_value.args), traceback)
	  File "/usr/local/lib/python2.7/dist-packages/peewee.py", line 2153, in execute_sql
	    res = cursor.execute(sql, params or ())
	peewee.InternalError: current transaction is aborted, commands ignored until end of transaction block
	
	
2014-02-10 16:15:29+0800 [taobao] ERROR: Error processing {'flag': 'Seller',
	 'name': u'\u5357\u6ce2\u4e071',
	 'positiveFeedbackRate': 99.81,
	 'reputScore': 5001,
	 'sellerId': 37213332,
	 'shopDesc': [4.9, 4.8, 4.9]}
	Traceback (most recent call last):
	  File "/usr/local/lib/python2.7/dist-packages/scrapy/middleware.py", line 62, in _process_chain
	    return process_chain(self.methods[methodname], obj, *args)
	  File "/usr/local/lib/python2.7/dist-packages/scrapy/utils/defer.py", line 65, in process_chain
	    d.callback(input)
	  File "/usr/local/lib/python2.7/dist-packages/twisted/internet/defer.py", line 382, in callback
	    self._startRunCallbacks(result)
	  File "/usr/local/lib/python2.7/dist-packages/twisted/internet/defer.py", line 490, in _startRunCallbacks
	    self._runCallbacks()
	--- <exception caught here> ---
	  File "/usr/local/lib/python2.7/dist-packages/twisted/internet/defer.py", line 577, in _runCallbacks
	    current.result = callback(current.result, *args, **kw)
	  File "/home/zq/Project/taobao/taobao/pipelines.py", line 22, in process_item
	    seller.save()
	  File "/usr/local/lib/python2.7/dist-packages/peewee.py", line 2837, in save
	    ret_pk = self.insert(**field_dict).execute()
	  File "/usr/local/lib/python2.7/dist-packages/peewee.py", line 2000, in execute
	    return self.database.last_insert_id(self._execute(), self.model_class)
	  File "/usr/local/lib/python2.7/dist-packages/peewee.py", line 1671, in _execute
	    return self.database.execute_sql(sql, params, self.require_commit)
	  File "/usr/local/lib/python2.7/dist-packages/peewee.py", line 2162, in execute_sql
	    self.commit()
	  File "/usr/local/lib/python2.7/dist-packages/peewee.py", line 2036, in __exit__
	    reraise(new_type, new_type(*exc_value.args), traceback)
	  File "/usr/local/lib/python2.7/dist-packages/peewee.py", line 2153, in execute_sql
	    res = cursor.execute(sql, params or ())
	peewee.InternalError: current transaction is aborted, commands ignored until end of transaction block
	
	
2014-02-10 16:15:29+0800 [taobao] ERROR: Error processing {'flag': 'Seller',
	 'name': u'\u5148\u950b\u6218\u58eb01',
	 'positiveFeedbackRate': 99.38,
	 'reputScore': 10001,
	 'sellerId': 470823318,
	 'shopDesc': [4.8, 4.8, 4.8]}
	Traceback (most recent call last):
	  File "/usr/local/lib/python2.7/dist-packages/scrapy/middleware.py", line 62, in _process_chain
	    return process_chain(self.methods[methodname], obj, *args)
	  File "/usr/local/lib/python2.7/dist-packages/scrapy/utils/defer.py", line 65, in process_chain
	    d.callback(input)
	  File "/usr/local/lib/python2.7/dist-packages/twisted/internet/defer.py", line 382, in callback
	    self._startRunCallbacks(result)
	  File "/usr/local/lib/python2.7/dist-packages/twisted/internet/defer.py", line 490, in _startRunCallbacks
	    self._runCallbacks()
	--- <exception caught here> ---
	  File "/usr/local/lib/python2.7/dist-packages/twisted/internet/defer.py", line 577, in _runCallbacks
	    current.result = callback(current.result, *args, **kw)
	  File "/home/zq/Project/taobao/taobao/pipelines.py", line 22, in process_item
	    seller.save()
	  File "/usr/local/lib/python2.7/dist-packages/peewee.py", line 2837, in save
	    ret_pk = self.insert(**field_dict).execute()
	  File "/usr/local/lib/python2.7/dist-packages/peewee.py", line 2000, in execute
	    return self.database.last_insert_id(self._execute(), self.model_class)
	  File "/usr/local/lib/python2.7/dist-packages/peewee.py", line 1671, in _execute
	    return self.database.execute_sql(sql, params, self.require_commit)
	  File "/usr/local/lib/python2.7/dist-packages/peewee.py", line 2162, in execute_sql
	    self.commit()
	  File "/usr/local/lib/python2.7/dist-packages/peewee.py", line 2036, in __exit__
	    reraise(new_type, new_type(*exc_value.args), traceback)
	  File "/usr/local/lib/python2.7/dist-packages/peewee.py", line 2153, in execute_sql
	    res = cursor.execute(sql, params or ())
	peewee.InternalError: current transaction is aborted, commands ignored until end of transaction block
	
	
2014-02-10 16:15:29+0800 [taobao] ERROR: Error processing {'flag': 'Seller',
	 'name': u'\u5c0f\u745e\u4ed4',
	 'positiveFeedbackRate': 99.56,
	 'reputScore': 20001,
	 'sellerId': 48788909,
	 'shopDesc': [4.9, 4.9, 4.9]}
	Traceback (most recent call last):
	  File "/usr/local/lib/python2.7/dist-packages/scrapy/middleware.py", line 62, in _process_chain
	    return process_chain(self.methods[methodname], obj, *args)
	  File "/usr/local/lib/python2.7/dist-packages/scrapy/utils/defer.py", line 65, in process_chain
	    d.callback(input)
	  File "/usr/local/lib/python2.7/dist-packages/twisted/internet/defer.py", line 382, in callback
	    self._startRunCallbacks(result)
	  File "/usr/local/lib/python2.7/dist-packages/twisted/internet/defer.py", line 490, in _startRunCallbacks
	    self._runCallbacks()
	--- <exception caught here> ---
	  File "/usr/local/lib/python2.7/dist-packages/twisted/internet/defer.py", line 577, in _runCallbacks
	    current.result = callback(current.result, *args, **kw)
	  File "/home/zq/Project/taobao/taobao/pipelines.py", line 22, in process_item
	    seller.save()
	  File "/usr/local/lib/python2.7/dist-packages/peewee.py", line 2837, in save
	    ret_pk = self.insert(**field_dict).execute()
	  File "/usr/local/lib/python2.7/dist-packages/peewee.py", line 2000, in execute
	    return self.database.last_insert_id(self._execute(), self.model_class)
	  File "/usr/local/lib/python2.7/dist-packages/peewee.py", line 1671, in _execute
	    return self.database.execute_sql(sql, params, self.require_commit)
	  File "/usr/local/lib/python2.7/dist-packages/peewee.py", line 2162, in execute_sql
	    self.commit()
	  File "/usr/local/lib/python2.7/dist-packages/peewee.py", line 2036, in __exit__
	    reraise(new_type, new_type(*exc_value.args), traceback)
	  File "/usr/local/lib/python2.7/dist-packages/peewee.py", line 2153, in execute_sql
	    res = cursor.execute(sql, params or ())
	peewee.InternalError: current transaction is aborted, commands ignored until end of transaction block
	
	
2014-02-10 16:15:29+0800 [taobao] ERROR: Error processing {'flag': 'Seller',
	 'name': u'\u9b54\u529b\u901a\u8baf',
	 'positiveFeedbackRate': 99.78,
	 'reputScore': 20001,
	 'sellerId': 214498135,
	 'shopDesc': [4.8, 4.8, 4.8]}
	Traceback (most recent call last):
	  File "/usr/local/lib/python2.7/dist-packages/scrapy/middleware.py", line 62, in _process_chain
	    return process_chain(self.methods[methodname], obj, *args)
	  File "/usr/local/lib/python2.7/dist-packages/scrapy/utils/defer.py", line 65, in process_chain
	    d.callback(input)
	  File "/usr/local/lib/python2.7/dist-packages/twisted/internet/defer.py", line 382, in callback
	    self._startRunCallbacks(result)
	  File "/usr/local/lib/python2.7/dist-packages/twisted/internet/defer.py", line 490, in _startRunCallbacks
	    self._runCallbacks()
	--- <exception caught here> ---
	  File "/usr/local/lib/python2.7/dist-packages/twisted/internet/defer.py", line 577, in _runCallbacks
	    current.result = callback(current.result, *args, **kw)
	  File "/home/zq/Project/taobao/taobao/pipelines.py", line 22, in process_item
	    seller.save()
	  File "/usr/local/lib/python2.7/dist-packages/peewee.py", line 2837, in save
	    ret_pk = self.insert(**field_dict).execute()
	  File "/usr/local/lib/python2.7/dist-packages/peewee.py", line 2000, in execute
	    return self.database.last_insert_id(self._execute(), self.model_class)
	  File "/usr/local/lib/python2.7/dist-packages/peewee.py", line 1671, in _execute
	    return self.database.execute_sql(sql, params, self.require_commit)
	  File "/usr/local/lib/python2.7/dist-packages/peewee.py", line 2162, in execute_sql
	    self.commit()
	  File "/usr/local/lib/python2.7/dist-packages/peewee.py", line 2036, in __exit__
	    reraise(new_type, new_type(*exc_value.args), traceback)
	  File "/usr/local/lib/python2.7/dist-packages/peewee.py", line 2153, in execute_sql
	    res = cursor.execute(sql, params or ())
	peewee.InternalError: current transaction is aborted, commands ignored until end of transaction block
	
	
2014-02-10 16:15:29+0800 [taobao] ERROR: Error processing {'flag': 'Seller',
	 'name': u'ygsd',
	 'positiveFeedbackRate': 99.63,
	 'reputScore': 50001,
	 'sellerId': 898225,
	 'shopDesc': [4.8, 4.8, 4.8]}
	Traceback (most recent call last):
	  File "/usr/local/lib/python2.7/dist-packages/scrapy/middleware.py", line 62, in _process_chain
	    return process_chain(self.methods[methodname], obj, *args)
	  File "/usr/local/lib/python2.7/dist-packages/scrapy/utils/defer.py", line 65, in process_chain
	    d.callback(input)
	  File "/usr/local/lib/python2.7/dist-packages/twisted/internet/defer.py", line 382, in callback
	    self._startRunCallbacks(result)
	  File "/usr/local/lib/python2.7/dist-packages/twisted/internet/defer.py", line 490, in _startRunCallbacks
	    self._runCallbacks()
	--- <exception caught here> ---
	  File "/usr/local/lib/python2.7/dist-packages/twisted/internet/defer.py", line 577, in _runCallbacks
	    current.result = callback(current.result, *args, **kw)
	  File "/home/zq/Project/taobao/taobao/pipelines.py", line 22, in process_item
	    seller.save()
	  File "/usr/local/lib/python2.7/dist-packages/peewee.py", line 2837, in save
	    ret_pk = self.insert(**field_dict).execute()
	  File "/usr/local/lib/python2.7/dist-packages/peewee.py", line 2000, in execute
	    return self.database.last_insert_id(self._execute(), self.model_class)
	  File "/usr/local/lib/python2.7/dist-packages/peewee.py", line 1671, in _execute
	    return self.database.execute_sql(sql, params, self.require_commit)
	  File "/usr/local/lib/python2.7/dist-packages/peewee.py", line 2162, in execute_sql
	    self.commit()
	  File "/usr/local/lib/python2.7/dist-packages/peewee.py", line 2036, in __exit__
	    reraise(new_type, new_type(*exc_value.args), traceback)
	  File "/usr/local/lib/python2.7/dist-packages/peewee.py", line 2153, in execute_sql
	    res = cursor.execute(sql, params or ())
	peewee.InternalError: current transaction is aborted, commands ignored until end of transaction block
	
	
2014-02-10 16:15:29+0800 [taobao] ERROR: Error processing {'flag': 'Seller',
	 'name': u'\u6717\u6717\u7535\u73a9',
	 'positiveFeedbackRate': 99.67,
	 'reputScore': 20001,
	 'sellerId': 129307262,
	 'shopDesc': [4.8, 4.8, 4.9]}
	Traceback (most recent call last):
	  File "/usr/local/lib/python2.7/dist-packages/scrapy/middleware.py", line 62, in _process_chain
	    return process_chain(self.methods[methodname], obj, *args)
	  File "/usr/local/lib/python2.7/dist-packages/scrapy/utils/defer.py", line 65, in process_chain
	    d.callback(input)
	  File "/usr/local/lib/python2.7/dist-packages/twisted/internet/defer.py", line 382, in callback
	    self._startRunCallbacks(result)
	  File "/usr/local/lib/python2.7/dist-packages/twisted/internet/defer.py", line 490, in _startRunCallbacks
	    self._runCallbacks()
	--- <exception caught here> ---
	  File "/usr/local/lib/python2.7/dist-packages/twisted/internet/defer.py", line 577, in _runCallbacks
	    current.result = callback(current.result, *args, **kw)
	  File "/home/zq/Project/taobao/taobao/pipelines.py", line 22, in process_item
	    seller.save()
	  File "/usr/local/lib/python2.7/dist-packages/peewee.py", line 2837, in save
	    ret_pk = self.insert(**field_dict).execute()
	  File "/usr/local/lib/python2.7/dist-packages/peewee.py", line 2000, in execute
	    return self.database.last_insert_id(self._execute(), self.model_class)
	  File "/usr/local/lib/python2.7/dist-packages/peewee.py", line 1671, in _execute
	    return self.database.execute_sql(sql, params, self.require_commit)
	  File "/usr/local/lib/python2.7/dist-packages/peewee.py", line 2162, in execute_sql
	    self.commit()
	  File "/usr/local/lib/python2.7/dist-packages/peewee.py", line 2036, in __exit__
	    reraise(new_type, new_type(*exc_value.args), traceback)
	  File "/usr/local/lib/python2.7/dist-packages/peewee.py", line 2153, in execute_sql
	    res = cursor.execute(sql, params or ())
	peewee.InternalError: current transaction is aborted, commands ignored until end of transaction block
	
	
2014-02-10 16:15:29+0800 [taobao] ERROR: Error processing {'flag': 'Seller',
	 'name': u'yyxming',
	 'positiveFeedbackRate': 99.26,
	 'reputScore': 10001,
	 'sellerId': 441017263,
	 'shopDesc': [4.8, 4.8, 4.8]}
	Traceback (most recent call last):
	  File "/usr/local/lib/python2.7/dist-packages/scrapy/middleware.py", line 62, in _process_chain
	    return process_chain(self.methods[methodname], obj, *args)
	  File "/usr/local/lib/python2.7/dist-packages/scrapy/utils/defer.py", line 65, in process_chain
	    d.callback(input)
	  File "/usr/local/lib/python2.7/dist-packages/twisted/internet/defer.py", line 382, in callback
	    self._startRunCallbacks(result)
	  File "/usr/local/lib/python2.7/dist-packages/twisted/internet/defer.py", line 490, in _startRunCallbacks
	    self._runCallbacks()
	--- <exception caught here> ---
	  File "/usr/local/lib/python2.7/dist-packages/twisted/internet/defer.py", line 577, in _runCallbacks
	    current.result = callback(current.result, *args, **kw)
	  File "/home/zq/Project/taobao/taobao/pipelines.py", line 22, in process_item
	    seller.save()
	  File "/usr/local/lib/python2.7/dist-packages/peewee.py", line 2837, in save
	    ret_pk = self.insert(**field_dict).execute()
	  File "/usr/local/lib/python2.7/dist-packages/peewee.py", line 2000, in execute
	    return self.database.last_insert_id(self._execute(), self.model_class)
	  File "/usr/local/lib/python2.7/dist-packages/peewee.py", line 1671, in _execute
	    return self.database.execute_sql(sql, params, self.require_commit)
	  File "/usr/local/lib/python2.7/dist-packages/peewee.py", line 2162, in execute_sql
	    self.commit()
	  File "/usr/local/lib/python2.7/dist-packages/peewee.py", line 2036, in __exit__
	    reraise(new_type, new_type(*exc_value.args), traceback)
	  File "/usr/local/lib/python2.7/dist-packages/peewee.py", line 2153, in execute_sql
	    res = cursor.execute(sql, params or ())
	peewee.InternalError: current transaction is aborted, commands ignored until end of transaction block
	
	
2014-02-10 16:15:29+0800 [taobao] ERROR: Error processing {'flag': 'Seller',
	 'name': u'\u9999\u6e2f\u9ad8\u767b',
	 'positiveFeedbackRate': 99.9,
	 'reputScore': 5001,
	 'sellerId': 71011031,
	 'shopDesc': [4.9, 4.9, 4.9]}
	Traceback (most recent call last):
	  File "/usr/local/lib/python2.7/dist-packages/scrapy/middleware.py", line 62, in _process_chain
	    return process_chain(self.methods[methodname], obj, *args)
	  File "/usr/local/lib/python2.7/dist-packages/scrapy/utils/defer.py", line 65, in process_chain
	    d.callback(input)
	  File "/usr/local/lib/python2.7/dist-packages/twisted/internet/defer.py", line 382, in callback
	    self._startRunCallbacks(result)
	  File "/usr/local/lib/python2.7/dist-packages/twisted/internet/defer.py", line 490, in _startRunCallbacks
	    self._runCallbacks()
	--- <exception caught here> ---
	  File "/usr/local/lib/python2.7/dist-packages/twisted/internet/defer.py", line 577, in _runCallbacks
	    current.result = callback(current.result, *args, **kw)
	  File "/home/zq/Project/taobao/taobao/pipelines.py", line 22, in process_item
	    seller.save()
	  File "/usr/local/lib/python2.7/dist-packages/peewee.py", line 2837, in save
	    ret_pk = self.insert(**field_dict).execute()
	  File "/usr/local/lib/python2.7/dist-packages/peewee.py", line 2000, in execute
	    return self.database.last_insert_id(self._execute(), self.model_class)
	  File "/usr/local/lib/python2.7/dist-packages/peewee.py", line 1671, in _execute
	    return self.database.execute_sql(sql, params, self.require_commit)
	  File "/usr/local/lib/python2.7/dist-packages/peewee.py", line 2162, in execute_sql
	    self.commit()
	  File "/usr/local/lib/python2.7/dist-packages/peewee.py", line 2036, in __exit__
	    reraise(new_type, new_type(*exc_value.args), traceback)
	  File "/usr/local/lib/python2.7/dist-packages/peewee.py", line 2153, in execute_sql
	    res = cursor.execute(sql, params or ())
	peewee.InternalError: current transaction is aborted, commands ignored until end of transaction block
	
	
2014-02-10 16:15:29+0800 [taobao] ERROR: Error processing {'flag': 'Seller',
	 'name': u'binakong_bk',
	 'positiveFeedbackRate': 99.37,
	 'reputScore': 20001,
	 'sellerId': 325959470,
	 'shopDesc': [4.8, 4.8, 4.8]}
	Traceback (most recent call last):
	  File "/usr/local/lib/python2.7/dist-packages/scrapy/middleware.py", line 62, in _process_chain
	    return process_chain(self.methods[methodname], obj, *args)
	  File "/usr/local/lib/python2.7/dist-packages/scrapy/utils/defer.py", line 65, in process_chain
	    d.callback(input)
	  File "/usr/local/lib/python2.7/dist-packages/twisted/internet/defer.py", line 382, in callback
	    self._startRunCallbacks(result)
	  File "/usr/local/lib/python2.7/dist-packages/twisted/internet/defer.py", line 490, in _startRunCallbacks
	    self._runCallbacks()
	--- <exception caught here> ---
	  File "/usr/local/lib/python2.7/dist-packages/twisted/internet/defer.py", line 577, in _runCallbacks
	    current.result = callback(current.result, *args, **kw)
	  File "/home/zq/Project/taobao/taobao/pipelines.py", line 22, in process_item
	    seller.save()
	  File "/usr/local/lib/python2.7/dist-packages/peewee.py", line 2837, in save
	    ret_pk = self.insert(**field_dict).execute()
	  File "/usr/local/lib/python2.7/dist-packages/peewee.py", line 2000, in execute
	    return self.database.last_insert_id(self._execute(), self.model_class)
	  File "/usr/local/lib/python2.7/dist-packages/peewee.py", line 1671, in _execute
	    return self.database.execute_sql(sql, params, self.require_commit)
	  File "/usr/local/lib/python2.7/dist-packages/peewee.py", line 2162, in execute_sql
	    self.commit()
	  File "/usr/local/lib/python2.7/dist-packages/peewee.py", line 2036, in __exit__
	    reraise(new_type, new_type(*exc_value.args), traceback)
	  File "/usr/local/lib/python2.7/dist-packages/peewee.py", line 2153, in execute_sql
	    res = cursor.execute(sql, params or ())
	peewee.InternalError: current transaction is aborted, commands ignored until end of transaction block
	
	
2014-02-10 16:15:29+0800 [taobao] ERROR: Error processing {'flag': 'Seller',
	 'name': u'\u53f6\u6842\u624d\u5b9d\u8d1d',
	 'positiveFeedbackRate': 99.73,
	 'reputScore': 2001,
	 'sellerId': 70296483,
	 'shopDesc': [4.8, 4.8, 4.8]}
	Traceback (most recent call last):
	  File "/usr/local/lib/python2.7/dist-packages/scrapy/middleware.py", line 62, in _process_chain
	    return process_chain(self.methods[methodname], obj, *args)
	  File "/usr/local/lib/python2.7/dist-packages/scrapy/utils/defer.py", line 65, in process_chain
	    d.callback(input)
	  File "/usr/local/lib/python2.7/dist-packages/twisted/internet/defer.py", line 382, in callback
	    self._startRunCallbacks(result)
	  File "/usr/local/lib/python2.7/dist-packages/twisted/internet/defer.py", line 490, in _startRunCallbacks
	    self._runCallbacks()
	--- <exception caught here> ---
	  File "/usr/local/lib/python2.7/dist-packages/twisted/internet/defer.py", line 577, in _runCallbacks
	    current.result = callback(current.result, *args, **kw)
	  File "/home/zq/Project/taobao/taobao/pipelines.py", line 22, in process_item
	    seller.save()
	  File "/usr/local/lib/python2.7/dist-packages/peewee.py", line 2837, in save
	    ret_pk = self.insert(**field_dict).execute()
	  File "/usr/local/lib/python2.7/dist-packages/peewee.py", line 2000, in execute
	    return self.database.last_insert_id(self._execute(), self.model_class)
	  File "/usr/local/lib/python2.7/dist-packages/peewee.py", line 1671, in _execute
	    return self.database.execute_sql(sql, params, self.require_commit)
	  File "/usr/local/lib/python2.7/dist-packages/peewee.py", line 2162, in execute_sql
	    self.commit()
	  File "/usr/local/lib/python2.7/dist-packages/peewee.py", line 2036, in __exit__
	    reraise(new_type, new_type(*exc_value.args), traceback)
	  File "/usr/local/lib/python2.7/dist-packages/peewee.py", line 2153, in execute_sql
	    res = cursor.execute(sql, params or ())
	peewee.InternalError: current transaction is aborted, commands ignored until end of transaction block
	
	
2014-02-10 16:15:29+0800 [taobao] ERROR: Error processing {'flag': 'Seller',
	 'name': u'lemonlove_2008',
	 'positiveFeedbackRate': 99.26,
	 'reputScore': 5001,
	 'sellerId': 101209807,
	 'shopDesc': [4.8, 4.8, 4.8]}
	Traceback (most recent call last):
	  File "/usr/local/lib/python2.7/dist-packages/scrapy/middleware.py", line 62, in _process_chain
	    return process_chain(self.methods[methodname], obj, *args)
	  File "/usr/local/lib/python2.7/dist-packages/scrapy/utils/defer.py", line 65, in process_chain
	    d.callback(input)
	  File "/usr/local/lib/python2.7/dist-packages/twisted/internet/defer.py", line 382, in callback
	    self._startRunCallbacks(result)
	  File "/usr/local/lib/python2.7/dist-packages/twisted/internet/defer.py", line 490, in _startRunCallbacks
	    self._runCallbacks()
	--- <exception caught here> ---
	  File "/usr/local/lib/python2.7/dist-packages/twisted/internet/defer.py", line 577, in _runCallbacks
	    current.result = callback(current.result, *args, **kw)
	  File "/home/zq/Project/taobao/taobao/pipelines.py", line 22, in process_item
	    seller.save()
	  File "/usr/local/lib/python2.7/dist-packages/peewee.py", line 2837, in save
	    ret_pk = self.insert(**field_dict).execute()
	  File "/usr/local/lib/python2.7/dist-packages/peewee.py", line 2000, in execute
	    return self.database.last_insert_id(self._execute(), self.model_class)
	  File "/usr/local/lib/python2.7/dist-packages/peewee.py", line 1671, in _execute
	    return self.database.execute_sql(sql, params, self.require_commit)
	  File "/usr/local/lib/python2.7/dist-packages/peewee.py", line 2162, in execute_sql
	    self.commit()
	  File "/usr/local/lib/python2.7/dist-packages/peewee.py", line 2036, in __exit__
	    reraise(new_type, new_type(*exc_value.args), traceback)
	  File "/usr/local/lib/python2.7/dist-packages/peewee.py", line 2153, in execute_sql
	    res = cursor.execute(sql, params or ())
	peewee.InternalError: current transaction is aborted, commands ignored until end of transaction block
	
	
2014-02-10 16:15:29+0800 [taobao] ERROR: Error processing {'flag': 'Seller',
	 'name': u'\u706b\u9e92\u9e9f_\u6570\u7801',
	 'positiveFeedbackRate': 99.85,
	 'reputScore': 501,
	 'sellerId': 94092456,
	 'shopDesc': [4.9, 4.9, 4.9]}
	Traceback (most recent call last):
	  File "/usr/local/lib/python2.7/dist-packages/scrapy/middleware.py", line 62, in _process_chain
	    return process_chain(self.methods[methodname], obj, *args)
	  File "/usr/local/lib/python2.7/dist-packages/scrapy/utils/defer.py", line 65, in process_chain
	    d.callback(input)
	  File "/usr/local/lib/python2.7/dist-packages/twisted/internet/defer.py", line 382, in callback
	    self._startRunCallbacks(result)
	  File "/usr/local/lib/python2.7/dist-packages/twisted/internet/defer.py", line 490, in _startRunCallbacks
	    self._runCallbacks()
	--- <exception caught here> ---
	  File "/usr/local/lib/python2.7/dist-packages/twisted/internet/defer.py", line 577, in _runCallbacks
	    current.result = callback(current.result, *args, **kw)
	  File "/home/zq/Project/taobao/taobao/pipelines.py", line 22, in process_item
	    seller.save()
	  File "/usr/local/lib/python2.7/dist-packages/peewee.py", line 2837, in save
	    ret_pk = self.insert(**field_dict).execute()
	  File "/usr/local/lib/python2.7/dist-packages/peewee.py", line 2000, in execute
	    return self.database.last_insert_id(self._execute(), self.model_class)
	  File "/usr/local/lib/python2.7/dist-packages/peewee.py", line 1671, in _execute
	    return self.database.execute_sql(sql, params, self.require_commit)
	  File "/usr/local/lib/python2.7/dist-packages/peewee.py", line 2162, in execute_sql
	    self.commit()
	  File "/usr/local/lib/python2.7/dist-packages/peewee.py", line 2036, in __exit__
	    reraise(new_type, new_type(*exc_value.args), traceback)
	  File "/usr/local/lib/python2.7/dist-packages/peewee.py", line 2153, in execute_sql
	    res = cursor.execute(sql, params or ())
	peewee.InternalError: current transaction is aborted, commands ignored until end of transaction block
	
	
2014-02-10 16:15:29+0800 [taobao] ERROR: Error processing {'flag': 'Seller',
	 'name': u'\u6c81\u5fc3\u6570\u7801\u9601',
	 'positiveFeedbackRate': 99.62,
	 'reputScore': 1001,
	 'sellerId': 761145597,
	 'shopDesc': [4.9, 4.9, 4.9]}
	Traceback (most recent call last):
	  File "/usr/local/lib/python2.7/dist-packages/scrapy/middleware.py", line 62, in _process_chain
	    return process_chain(self.methods[methodname], obj, *args)
	  File "/usr/local/lib/python2.7/dist-packages/scrapy/utils/defer.py", line 65, in process_chain
	    d.callback(input)
	  File "/usr/local/lib/python2.7/dist-packages/twisted/internet/defer.py", line 382, in callback
	    self._startRunCallbacks(result)
	  File "/usr/local/lib/python2.7/dist-packages/twisted/internet/defer.py", line 490, in _startRunCallbacks
	    self._runCallbacks()
	--- <exception caught here> ---
	  File "/usr/local/lib/python2.7/dist-packages/twisted/internet/defer.py", line 577, in _runCallbacks
	    current.result = callback(current.result, *args, **kw)
	  File "/home/zq/Project/taobao/taobao/pipelines.py", line 22, in process_item
	    seller.save()
	  File "/usr/local/lib/python2.7/dist-packages/peewee.py", line 2837, in save
	    ret_pk = self.insert(**field_dict).execute()
	  File "/usr/local/lib/python2.7/dist-packages/peewee.py", line 2000, in execute
	    return self.database.last_insert_id(self._execute(), self.model_class)
	  File "/usr/local/lib/python2.7/dist-packages/peewee.py", line 1671, in _execute
	    return self.database.execute_sql(sql, params, self.require_commit)
	  File "/usr/local/lib/python2.7/dist-packages/peewee.py", line 2162, in execute_sql
	    self.commit()
	  File "/usr/local/lib/python2.7/dist-packages/peewee.py", line 2036, in __exit__
	    reraise(new_type, new_type(*exc_value.args), traceback)
	  File "/usr/local/lib/python2.7/dist-packages/peewee.py", line 2153, in execute_sql
	    res = cursor.execute(sql, params or ())
	peewee.InternalError: current transaction is aborted, commands ignored until end of transaction block
	
	
2014-02-10 16:15:29+0800 [taobao] ERROR: Error processing {'commId': 35338216935L,
	 'flag': 'Commodity',
	 'rateNumber': 331,
	 'sellerId': 376799512,
	 'title': u'\u539f\u5c01\u672a\u6fc0\u6d3bApple/\u82f9\u679c iPhone 5\u4ee3 \u5168\u65b0\u65e0\u9501 \u4e24\u7f51\u4e09\u7f51\u7535\u4fe13G\u624b\u673a',
	 'turnover': 249}
	Traceback (most recent call last):
	  File "/usr/local/lib/python2.7/dist-packages/scrapy/middleware.py", line 62, in _process_chain
	    return process_chain(self.methods[methodname], obj, *args)
	  File "/usr/local/lib/python2.7/dist-packages/scrapy/utils/defer.py", line 65, in process_chain
	    d.callback(input)
	  File "/usr/local/lib/python2.7/dist-packages/twisted/internet/defer.py", line 382, in callback
	    self._startRunCallbacks(result)
	  File "/usr/local/lib/python2.7/dist-packages/twisted/internet/defer.py", line 490, in _startRunCallbacks
	    self._runCallbacks()
	--- <exception caught here> ---
	  File "/usr/local/lib/python2.7/dist-packages/twisted/internet/defer.py", line 577, in _runCallbacks
	    current.result = callback(current.result, *args, **kw)
	  File "/home/zq/Project/taobao/taobao/pipelines.py", line 30, in process_item
	    commodity.save()
	  File "/usr/local/lib/python2.7/dist-packages/peewee.py", line 2837, in save
	    ret_pk = self.insert(**field_dict).execute()
	  File "/usr/local/lib/python2.7/dist-packages/peewee.py", line 2000, in execute
	    return self.database.last_insert_id(self._execute(), self.model_class)
	  File "/usr/local/lib/python2.7/dist-packages/peewee.py", line 1671, in _execute
	    return self.database.execute_sql(sql, params, self.require_commit)
	  File "/usr/local/lib/python2.7/dist-packages/peewee.py", line 2162, in execute_sql
	    self.commit()
	  File "/usr/local/lib/python2.7/dist-packages/peewee.py", line 2036, in __exit__
	    reraise(new_type, new_type(*exc_value.args), traceback)
	  File "/usr/local/lib/python2.7/dist-packages/peewee.py", line 2153, in execute_sql
	    res = cursor.execute(sql, params or ())
	peewee.InternalError: current transaction is aborted, commands ignored until end of transaction block
	
	
2014-02-10 16:15:29+0800 [taobao] ERROR: Error processing {'commId': 27610584433L,
	 'flag': 'Commodity',
	 'rateNumber': 14905,
	 'sellerId': 380624657,
	 'title': u'\u5a01\u950b\u8ba4\u8bc1 \u6b63\u54c1\u4fdd\u969c \u5f53\u5929\u53d1\u8d27 Apple/\u82f9\u679c iPhone 5S \u6b63\u6e2f v\u7248\u4e09\u7f51',
	 'turnover': 6916}
	Traceback (most recent call last):
	  File "/usr/local/lib/python2.7/dist-packages/scrapy/middleware.py", line 62, in _process_chain
	    return process_chain(self.methods[methodname], obj, *args)
	  File "/usr/local/lib/python2.7/dist-packages/scrapy/utils/defer.py", line 65, in process_chain
	    d.callback(input)
	  File "/usr/local/lib/python2.7/dist-packages/twisted/internet/defer.py", line 382, in callback
	    self._startRunCallbacks(result)
	  File "/usr/local/lib/python2.7/dist-packages/twisted/internet/defer.py", line 490, in _startRunCallbacks
	    self._runCallbacks()
	--- <exception caught here> ---
	  File "/usr/local/lib/python2.7/dist-packages/twisted/internet/defer.py", line 577, in _runCallbacks
	    current.result = callback(current.result, *args, **kw)
	  File "/home/zq/Project/taobao/taobao/pipelines.py", line 30, in process_item
	    commodity.save()
	  File "/usr/local/lib/python2.7/dist-packages/peewee.py", line 2837, in save
	    ret_pk = self.insert(**field_dict).execute()
	  File "/usr/local/lib/python2.7/dist-packages/peewee.py", line 2000, in execute
	    return self.database.last_insert_id(self._execute(), self.model_class)
	  File "/usr/local/lib/python2.7/dist-packages/peewee.py", line 1671, in _execute
	    return self.database.execute_sql(sql, params, self.require_commit)
	  File "/usr/local/lib/python2.7/dist-packages/peewee.py", line 2162, in execute_sql
	    self.commit()
	  File "/usr/local/lib/python2.7/dist-packages/peewee.py", line 2036, in __exit__
	    reraise(new_type, new_type(*exc_value.args), traceback)
	  File "/usr/local/lib/python2.7/dist-packages/peewee.py", line 2153, in execute_sql
	    res = cursor.execute(sql, params or ())
	peewee.InternalError: current transaction is aborted, commands ignored until end of transaction block
	
	
2014-02-10 16:15:29+0800 [taobao] ERROR: Error processing {'commId': 20098897075L,
	 'flag': 'Commodity',
	 'rateNumber': 6552,
	 'sellerId': 12573474,
	 'title': u'Apple/\u82f9\u679c iPhone 5S\u82f9\u679c5S \u4e09\u7f51V\u7248 \u6e2f\u7248\u672a\u6fc0\u6d3b\u3010\u6625\u8282\u4e0d\u6253\u70ca\u3011',
	 'turnover': 2902}
	Traceback (most recent call last):
	  File "/usr/local/lib/python2.7/dist-packages/scrapy/middleware.py", line 62, in _process_chain
	    return process_chain(self.methods[methodname], obj, *args)
	  File "/usr/local/lib/python2.7/dist-packages/scrapy/utils/defer.py", line 65, in process_chain
	    d.callback(input)
	  File "/usr/local/lib/python2.7/dist-packages/twisted/internet/defer.py", line 382, in callback
	    self._startRunCallbacks(result)
	  File "/usr/local/lib/python2.7/dist-packages/twisted/internet/defer.py", line 490, in _startRunCallbacks
	    self._runCallbacks()
	--- <exception caught here> ---
	  File "/usr/local/lib/python2.7/dist-packages/twisted/internet/defer.py", line 577, in _runCallbacks
	    current.result = callback(current.result, *args, **kw)
	  File "/home/zq/Project/taobao/taobao/pipelines.py", line 30, in process_item
	    commodity.save()
	  File "/usr/local/lib/python2.7/dist-packages/peewee.py", line 2837, in save
	    ret_pk = self.insert(**field_dict).execute()
	  File "/usr/local/lib/python2.7/dist-packages/peewee.py", line 2000, in execute
	    return self.database.last_insert_id(self._execute(), self.model_class)
	  File "/usr/local/lib/python2.7/dist-packages/peewee.py", line 1671, in _execute
	    return self.database.execute_sql(sql, params, self.require_commit)
	  File "/usr/local/lib/python2.7/dist-packages/peewee.py", line 2162, in execute_sql
	    self.commit()
	  File "/usr/local/lib/python2.7/dist-packages/peewee.py", line 2036, in __exit__
	    reraise(new_type, new_type(*exc_value.args), traceback)
	  File "/usr/local/lib/python2.7/dist-packages/peewee.py", line 2153, in execute_sql
	    res = cursor.execute(sql, params or ())
	peewee.InternalError: current transaction is aborted, commands ignored until end of transaction block
	
	
2014-02-10 16:15:29+0800 [taobao] ERROR: Error processing {'commId': 21894319337L,
	 'flag': 'Commodity',
	 'rateNumber': 6357,
	 'sellerId': 853982,
	 'title': u'\u3010\u60c5\u4eba\u8282\u7279\u4ef7\u3011Apple/\u82f9\u679c iPhone 5S\u82f9\u679c5s \u79fb\u52a84G\u7248 \u4e09\u7f51\u7535\u4fe1\u7248',
	 'turnover': 3637}
	Traceback (most recent call last):
	  File "/usr/local/lib/python2.7/dist-packages/scrapy/middleware.py", line 62, in _process_chain
	    return process_chain(self.methods[methodname], obj, *args)
	  File "/usr/local/lib/python2.7/dist-packages/scrapy/utils/defer.py", line 65, in process_chain
	    d.callback(input)
	  File "/usr/local/lib/python2.7/dist-packages/twisted/internet/defer.py", line 382, in callback
	    self._startRunCallbacks(result)
	  File "/usr/local/lib/python2.7/dist-packages/twisted/internet/defer.py", line 490, in _startRunCallbacks
	    self._runCallbacks()
	--- <exception caught here> ---
	  File "/usr/local/lib/python2.7/dist-packages/twisted/internet/defer.py", line 577, in _runCallbacks
	    current.result = callback(current.result, *args, **kw)
	  File "/home/zq/Project/taobao/taobao/pipelines.py", line 30, in process_item
	    commodity.save()
	  File "/usr/local/lib/python2.7/dist-packages/peewee.py", line 2837, in save
	    ret_pk = self.insert(**field_dict).execute()
	  File "/usr/local/lib/python2.7/dist-packages/peewee.py", line 2000, in execute
	    return self.database.last_insert_id(self._execute(), self.model_class)
	  File "/usr/local/lib/python2.7/dist-packages/peewee.py", line 1671, in _execute
	    return self.database.execute_sql(sql, params, self.require_commit)
	  File "/usr/local/lib/python2.7/dist-packages/peewee.py", line 2162, in execute_sql
	    self.commit()
	  File "/usr/local/lib/python2.7/dist-packages/peewee.py", line 2036, in __exit__
	    reraise(new_type, new_type(*exc_value.args), traceback)
	  File "/usr/local/lib/python2.7/dist-packages/peewee.py", line 2153, in execute_sql
	    res = cursor.execute(sql, params or ())
	peewee.InternalError: current transaction is aborted, commands ignored until end of transaction block
	
	
2014-02-10 16:15:29+0800 [taobao] ERROR: Error processing {'commId': 20128886326L,
	 'flag': 'Commodity',
	 'rateNumber': 2343,
	 'sellerId': 183262695,
	 'title': u'\u3010\u571f\u8c6a\u91d1\u7279\u4ef7.4120\u3011Apple/\u82f9\u679c iPhone 5S \u82f9\u679c5S \u6e2f\u7248 \u4e09\u7f51V\u7248',
	 'turnover': 2325}
	Traceback (most recent call last):
	  File "/usr/local/lib/python2.7/dist-packages/scrapy/middleware.py", line 62, in _process_chain
	    return process_chain(self.methods[methodname], obj, *args)
	  File "/usr/local/lib/python2.7/dist-packages/scrapy/utils/defer.py", line 65, in process_chain
	    d.callback(input)
	  File "/usr/local/lib/python2.7/dist-packages/twisted/internet/defer.py", line 382, in callback
	    self._startRunCallbacks(result)
	  File "/usr/local/lib/python2.7/dist-packages/twisted/internet/defer.py", line 490, in _startRunCallbacks
	    self._runCallbacks()
	--- <exception caught here> ---
	  File "/usr/local/lib/python2.7/dist-packages/twisted/internet/defer.py", line 577, in _runCallbacks
	    current.result = callback(current.result, *args, **kw)
	  File "/home/zq/Project/taobao/taobao/pipelines.py", line 30, in process_item
	    commodity.save()
	  File "/usr/local/lib/python2.7/dist-packages/peewee.py", line 2837, in save
	    ret_pk = self.insert(**field_dict).execute()
	  File "/usr/local/lib/python2.7/dist-packages/peewee.py", line 2000, in execute
	    return self.database.last_insert_id(self._execute(), self.model_class)
	  File "/usr/local/lib/python2.7/dist-packages/peewee.py", line 1671, in _execute
	    return self.database.execute_sql(sql, params, self.require_commit)
	  File "/usr/local/lib/python2.7/dist-packages/peewee.py", line 2162, in execute_sql
	    self.commit()
	  File "/usr/local/lib/python2.7/dist-packages/peewee.py", line 2036, in __exit__
	    reraise(new_type, new_type(*exc_value.args), traceback)
	  File "/usr/local/lib/python2.7/dist-packages/peewee.py", line 2153, in execute_sql
	    res = cursor.execute(sql, params or ())
	peewee.InternalError: current transaction is aborted, commands ignored until end of transaction block
	
	
2014-02-10 16:15:29+0800 [taobao] ERROR: Error processing {'commId': 20123225215L,
	 'flag': 'Commodity',
	 'rateNumber': 5272,
	 'sellerId': 20543624,
	 'title': u'\u5a01\u950b\u8ba4\u8bc1 Apple/\u82f9\u679c iPhone 5S \u82f9\u679c5S \u6e2f\u7248\u539f\u5c01 V\u7248\u4e09\u7f51\u7535\u4fe1',
	 'turnover': 2772}
	Traceback (most recent call last):
	  File "/usr/local/lib/python2.7/dist-packages/scrapy/middleware.py", line 62, in _process_chain
	    return process_chain(self.methods[methodname], obj, *args)
	  File "/usr/local/lib/python2.7/dist-packages/scrapy/utils/defer.py", line 65, in process_chain
	    d.callback(input)
	  File "/usr/local/lib/python2.7/dist-packages/twisted/internet/defer.py", line 382, in callback
	    self._startRunCallbacks(result)
	  File "/usr/local/lib/python2.7/dist-packages/twisted/internet/defer.py", line 490, in _startRunCallbacks
	    self._runCallbacks()
	--- <exception caught here> ---
	  File "/usr/local/lib/python2.7/dist-packages/twisted/internet/defer.py", line 577, in _runCallbacks
	    current.result = callback(current.result, *args, **kw)
	  File "/home/zq/Project/taobao/taobao/pipelines.py", line 30, in process_item
	    commodity.save()
	  File "/usr/local/lib/python2.7/dist-packages/peewee.py", line 2837, in save
	    ret_pk = self.insert(**field_dict).execute()
	  File "/usr/local/lib/python2.7/dist-packages/peewee.py", line 2000, in execute
	    return self.database.last_insert_id(self._execute(), self.model_class)
	  File "/usr/local/lib/python2.7/dist-packages/peewee.py", line 1671, in _execute
	    return self.database.execute_sql(sql, params, self.require_commit)
	  File "/usr/local/lib/python2.7/dist-packages/peewee.py", line 2162, in execute_sql
	    self.commit()
	  File "/usr/local/lib/python2.7/dist-packages/peewee.py", line 2036, in __exit__
	    reraise(new_type, new_type(*exc_value.args), traceback)
	  File "/usr/local/lib/python2.7/dist-packages/peewee.py", line 2153, in execute_sql
	    res = cursor.execute(sql, params or ())
	peewee.InternalError: current transaction is aborted, commands ignored until end of transaction block
	
	
2014-02-10 16:15:29+0800 [taobao] ERROR: Error processing {'commId': 19904928406L,
	 'flag': 'Commodity',
	 'rateNumber': 477,
	 'sellerId': 118130847,
	 'title': u'Apple/\u82f9\u679c iPhone 5S\u6e2f\u7248 \u5168\u65b0\u9999\u6e2f\u5b98\u7f51\u4ee3\u8d2d\u539f\u5c01\u725b\u76ae\u7eb8\u76d2\u5e26\u7968',
	 'turnover': 522}
	Traceback (most recent call last):
	  File "/usr/local/lib/python2.7/dist-packages/scrapy/middleware.py", line 62, in _process_chain
	    return process_chain(self.methods[methodname], obj, *args)
	  File "/usr/local/lib/python2.7/dist-packages/scrapy/utils/defer.py", line 65, in process_chain
	    d.callback(input)
	  File "/usr/local/lib/python2.7/dist-packages/twisted/internet/defer.py", line 382, in callback
	    self._startRunCallbacks(result)
	  File "/usr/local/lib/python2.7/dist-packages/twisted/internet/defer.py", line 490, in _startRunCallbacks
	    self._runCallbacks()
	--- <exception caught here> ---
	  File "/usr/local/lib/python2.7/dist-packages/twisted/internet/defer.py", line 577, in _runCallbacks
	    current.result = callback(current.result, *args, **kw)
	  File "/home/zq/Project/taobao/taobao/pipelines.py", line 30, in process_item
	    commodity.save()
	  File "/usr/local/lib/python2.7/dist-packages/peewee.py", line 2837, in save
	    ret_pk = self.insert(**field_dict).execute()
	  File "/usr/local/lib/python2.7/dist-packages/peewee.py", line 2000, in execute
	    return self.database.last_insert_id(self._execute(), self.model_class)
	  File "/usr/local/lib/python2.7/dist-packages/peewee.py", line 1671, in _execute
	    return self.database.execute_sql(sql, params, self.require_commit)
	  File "/usr/local/lib/python2.7/dist-packages/peewee.py", line 2162, in execute_sql
	    self.commit()
	  File "/usr/local/lib/python2.7/dist-packages/peewee.py", line 2036, in __exit__
	    reraise(new_type, new_type(*exc_value.args), traceback)
	  File "/usr/local/lib/python2.7/dist-packages/peewee.py", line 2153, in execute_sql
	    res = cursor.execute(sql, params or ())
	peewee.InternalError: current transaction is aborted, commands ignored until end of transaction block
	
	
2014-02-10 16:15:29+0800 [taobao] ERROR: Error processing {'commId': 20152334720L,
	 'flag': 'Commodity',
	 'rateNumber': 2118,
	 'sellerId': 37830682,
	 'title': u'Apple/\u82f9\u679c iPhone 5S 16G\u4e09\u7f51\u901aV\u7248\u539f\u5c01\u6e2f\u884c\u571f\u8c6a\u91d1 \u9ed1\u767d\u82724168',
	 'turnover': 1194}
	Traceback (most recent call last):
	  File "/usr/local/lib/python2.7/dist-packages/scrapy/middleware.py", line 62, in _process_chain
	    return process_chain(self.methods[methodname], obj, *args)
	  File "/usr/local/lib/python2.7/dist-packages/scrapy/utils/defer.py", line 65, in process_chain
	    d.callback(input)
	  File "/usr/local/lib/python2.7/dist-packages/twisted/internet/defer.py", line 382, in callback
	    self._startRunCallbacks(result)
	  File "/usr/local/lib/python2.7/dist-packages/twisted/internet/defer.py", line 490, in _startRunCallbacks
	    self._runCallbacks()
	--- <exception caught here> ---
	  File "/usr/local/lib/python2.7/dist-packages/twisted/internet/defer.py", line 577, in _runCallbacks
	    current.result = callback(current.result, *args, **kw)
	  File "/home/zq/Project/taobao/taobao/pipelines.py", line 30, in process_item
	    commodity.save()
	  File "/usr/local/lib/python2.7/dist-packages/peewee.py", line 2837, in save
	    ret_pk = self.insert(**field_dict).execute()
	  File "/usr/local/lib/python2.7/dist-packages/peewee.py", line 2000, in execute
	    return self.database.last_insert_id(self._execute(), self.model_class)
	  File "/usr/local/lib/python2.7/dist-packages/peewee.py", line 1671, in _execute
	    return self.database.execute_sql(sql, params, self.require_commit)
	  File "/usr/local/lib/python2.7/dist-packages/peewee.py", line 2162, in execute_sql
	    self.commit()
	  File "/usr/local/lib/python2.7/dist-packages/peewee.py", line 2036, in __exit__
	    reraise(new_type, new_type(*exc_value.args), traceback)
	  File "/usr/local/lib/python2.7/dist-packages/peewee.py", line 2153, in execute_sql
	    res = cursor.execute(sql, params or ())
	peewee.InternalError: current transaction is aborted, commands ignored until end of transaction block
	
	
2014-02-10 16:15:29+0800 [taobao] ERROR: Error processing {'commId': 19974242521L,
	 'flag': 'Commodity',
	 'rateNumber': 5350,
	 'sellerId': 196118321,
	 'title': u'\u3010\u9650\u65f6\u9001\u94a2\u5316\u9632\u7206\u819c \u6e2f\u7248\u571f\u8c6a\u91d14278\u3011Apple/\u82f9\u679c iPhone 5S \u56fd\u884c',
	 'turnover': 1092}
	Traceback (most recent call last):
	  File "/usr/local/lib/python2.7/dist-packages/scrapy/middleware.py", line 62, in _process_chain
	    return process_chain(self.methods[methodname], obj, *args)
	  File "/usr/local/lib/python2.7/dist-packages/scrapy/utils/defer.py", line 65, in process_chain
	    d.callback(input)
	  File "/usr/local/lib/python2.7/dist-packages/twisted/internet/defer.py", line 382, in callback
	    self._startRunCallbacks(result)
	  File "/usr/local/lib/python2.7/dist-packages/twisted/internet/defer.py", line 490, in _startRunCallbacks
	    self._runCallbacks()
	--- <exception caught here> ---
	  File "/usr/local/lib/python2.7/dist-packages/twisted/internet/defer.py", line 577, in _runCallbacks
	    current.result = callback(current.result, *args, **kw)
	  File "/home/zq/Project/taobao/taobao/pipelines.py", line 30, in process_item
	    commodity.save()
	  File "/usr/local/lib/python2.7/dist-packages/peewee.py", line 2837, in save
	    ret_pk = self.insert(**field_dict).execute()
	  File "/usr/local/lib/python2.7/dist-packages/peewee.py", line 2000, in execute
	    return self.database.last_insert_id(self._execute(), self.model_class)
	  File "/usr/local/lib/python2.7/dist-packages/peewee.py", line 1671, in _execute
	    return self.database.execute_sql(sql, params, self.require_commit)
	  File "/usr/local/lib/python2.7/dist-packages/peewee.py", line 2162, in execute_sql
	    self.commit()
	  File "/usr/local/lib/python2.7/dist-packages/peewee.py", line 2036, in __exit__
	    reraise(new_type, new_type(*exc_value.args), traceback)
	  File "/usr/local/lib/python2.7/dist-packages/peewee.py", line 2153, in execute_sql
	    res = cursor.execute(sql, params or ())
	peewee.InternalError: current transaction is aborted, commands ignored until end of transaction block
	
	
2014-02-10 16:15:29+0800 [taobao] ERROR: Error processing {'commId': 20234961703L,
	 'flag': 'Commodity',
	 'rateNumber': 1945,
	 'sellerId': 141757951,
	 'title': u'\u5047\u4e00\u8d54\u4e07Apple/\u82f9\u679c iPhone5s \u82f9\u679c5S\u624b\u673a \u65e5\u7248\u7f8e\u7248 \u9001\u7ea2\u5305\u8fce\u65b0\u5e74',
	 'turnover': 777}
	Traceback (most recent call last):
	  File "/usr/local/lib/python2.7/dist-packages/scrapy/middleware.py", line 62, in _process_chain
	    return process_chain(self.methods[methodname], obj, *args)
	  File "/usr/local/lib/python2.7/dist-packages/scrapy/utils/defer.py", line 65, in process_chain
	    d.callback(input)
	  File "/usr/local/lib/python2.7/dist-packages/twisted/internet/defer.py", line 382, in callback
	    self._startRunCallbacks(result)
	  File "/usr/local/lib/python2.7/dist-packages/twisted/internet/defer.py", line 490, in _startRunCallbacks
	    self._runCallbacks()
	--- <exception caught here> ---
	  File "/usr/local/lib/python2.7/dist-packages/twisted/internet/defer.py", line 577, in _runCallbacks
	    current.result = callback(current.result, *args, **kw)
	  File "/home/zq/Project/taobao/taobao/pipelines.py", line 30, in process_item
	    commodity.save()
	  File "/usr/local/lib/python2.7/dist-packages/peewee.py", line 2837, in save
	    ret_pk = self.insert(**field_dict).execute()
	  File "/usr/local/lib/python2.7/dist-packages/peewee.py", line 2000, in execute
	    return self.database.last_insert_id(self._execute(), self.model_class)
	  File "/usr/local/lib/python2.7/dist-packages/peewee.py", line 1671, in _execute
	    return self.database.execute_sql(sql, params, self.require_commit)
	  File "/usr/local/lib/python2.7/dist-packages/peewee.py", line 2162, in execute_sql
	    self.commit()
	  File "/usr/local/lib/python2.7/dist-packages/peewee.py", line 2036, in __exit__
	    reraise(new_type, new_type(*exc_value.args), traceback)
	  File "/usr/local/lib/python2.7/dist-packages/peewee.py", line 2153, in execute_sql
	    res = cursor.execute(sql, params or ())
	peewee.InternalError: current transaction is aborted, commands ignored until end of transaction block
	
	
2014-02-10 16:15:29+0800 [taobao] ERROR: Error processing {'commId': 35239877266L,
	 'flag': 'Commodity',
	 'rateNumber': 279,
	 'sellerId': 688690474,
	 'title': u'Apple/\u82f9\u679c iPhone 5S\u6e2f\u7248 V\u7248\u4e09\u7f51 \u91d1\u8272\u4e00\u697c\u571f\u6728\u4eba \u6b63\u54c1\u5305\u90ae',
	 'turnover': 353}
	Traceback (most recent call last):
	  File "/usr/local/lib/python2.7/dist-packages/scrapy/middleware.py", line 62, in _process_chain
	    return process_chain(self.methods[methodname], obj, *args)
	  File "/usr/local/lib/python2.7/dist-packages/scrapy/utils/defer.py", line 65, in process_chain
	    d.callback(input)
	  File "/usr/local/lib/python2.7/dist-packages/twisted/internet/defer.py", line 382, in callback
	    self._startRunCallbacks(result)
	  File "/usr/local/lib/python2.7/dist-packages/twisted/internet/defer.py", line 490, in _startRunCallbacks
	    self._runCallbacks()
	--- <exception caught here> ---
	  File "/usr/local/lib/python2.7/dist-packages/twisted/internet/defer.py", line 577, in _runCallbacks
	    current.result = callback(current.result, *args, **kw)
	  File "/home/zq/Project/taobao/taobao/pipelines.py", line 30, in process_item
	    commodity.save()
	  File "/usr/local/lib/python2.7/dist-packages/peewee.py", line 2837, in save
	    ret_pk = self.insert(**field_dict).execute()
	  File "/usr/local/lib/python2.7/dist-packages/peewee.py", line 2000, in execute
	    return self.database.last_insert_id(self._execute(), self.model_class)
	  File "/usr/local/lib/python2.7/dist-packages/peewee.py", line 1671, in _execute
	    return self.database.execute_sql(sql, params, self.require_commit)
	  File "/usr/local/lib/python2.7/dist-packages/peewee.py", line 2162, in execute_sql
	    self.commit()
	  File "/usr/local/lib/python2.7/dist-packages/peewee.py", line 2036, in __exit__
	    reraise(new_type, new_type(*exc_value.args), traceback)
	  File "/usr/local/lib/python2.7/dist-packages/peewee.py", line 2153, in execute_sql
	    res = cursor.execute(sql, params or ())
	peewee.InternalError: current transaction is aborted, commands ignored until end of transaction block
	
	
2014-02-10 16:15:29+0800 [taobao] ERROR: Error processing {'commId': 22577235117L,
	 'flag': 'Commodity',
	 'rateNumber': 616,
	 'sellerId': 477135813,
	 'title': u'Apple/\u82f9\u679c iPhone 5S\u82f9\u679c5s \u6e2f\u7248\u539f\u5c01 \u6fb3\u7248V\u7248\u4e09\u7f51 \u571f\u8c6a\u91d14340',
	 'turnover': 508}
	Traceback (most recent call last):
	  File "/usr/local/lib/python2.7/dist-packages/scrapy/middleware.py", line 62, in _process_chain
	    return process_chain(self.methods[methodname], obj, *args)
	  File "/usr/local/lib/python2.7/dist-packages/scrapy/utils/defer.py", line 65, in process_chain
	    d.callback(input)
	  File "/usr/local/lib/python2.7/dist-packages/twisted/internet/defer.py", line 382, in callback
	    self._startRunCallbacks(result)
	  File "/usr/local/lib/python2.7/dist-packages/twisted/internet/defer.py", line 490, in _startRunCallbacks
	    self._runCallbacks()
	--- <exception caught here> ---
	  File "/usr/local/lib/python2.7/dist-packages/twisted/internet/defer.py", line 577, in _runCallbacks
	    current.result = callback(current.result, *args, **kw)
	  File "/home/zq/Project/taobao/taobao/pipelines.py", line 30, in process_item
	    commodity.save()
	  File "/usr/local/lib/python2.7/dist-packages/peewee.py", line 2837, in save
	    ret_pk = self.insert(**field_dict).execute()
	  File "/usr/local/lib/python2.7/dist-packages/peewee.py", line 2000, in execute
	    return self.database.last_insert_id(self._execute(), self.model_class)
	  File "/usr/local/lib/python2.7/dist-packages/peewee.py", line 1671, in _execute
	    return self.database.execute_sql(sql, params, self.require_commit)
	  File "/usr/local/lib/python2.7/dist-packages/peewee.py", line 2162, in execute_sql
	    self.commit()
	  File "/usr/local/lib/python2.7/dist-packages/peewee.py", line 2036, in __exit__
	    reraise(new_type, new_type(*exc_value.args), traceback)
	  File "/usr/local/lib/python2.7/dist-packages/peewee.py", line 2153, in execute_sql
	    res = cursor.execute(sql, params or ())
	peewee.InternalError: current transaction is aborted, commands ignored until end of transaction block
	
	
2014-02-10 16:15:29+0800 [taobao] ERROR: Error processing {'commId': 20285310137L,
	 'flag': 'Commodity',
	 'rateNumber': 387,
	 'sellerId': 387784786,
	 'title': u'Apple/\u82f9\u679c iPhone 5S \u6e2f\u72483G 4G  iPhone 5S V\u7248\u4e09\u7f51 \u73b0\u8d27\u5305\u90ae',
	 'turnover': 528}
	Traceback (most recent call last):
	  File "/usr/local/lib/python2.7/dist-packages/scrapy/middleware.py", line 62, in _process_chain
	    return process_chain(self.methods[methodname], obj, *args)
	  File "/usr/local/lib/python2.7/dist-packages/scrapy/utils/defer.py", line 65, in process_chain
	    d.callback(input)
	  File "/usr/local/lib/python2.7/dist-packages/twisted/internet/defer.py", line 382, in callback
	    self._startRunCallbacks(result)
	  File "/usr/local/lib/python2.7/dist-packages/twisted/internet/defer.py", line 490, in _startRunCallbacks
	    self._runCallbacks()
	--- <exception caught here> ---
	  File "/usr/local/lib/python2.7/dist-packages/twisted/internet/defer.py", line 577, in _runCallbacks
	    current.result = callback(current.result, *args, **kw)
	  File "/home/zq/Project/taobao/taobao/pipelines.py", line 30, in process_item
	    commodity.save()
	  File "/usr/local/lib/python2.7/dist-packages/peewee.py", line 2837, in save
	    ret_pk = self.insert(**field_dict).execute()
	  File "/usr/local/lib/python2.7/dist-packages/peewee.py", line 2000, in execute
	    return self.database.last_insert_id(self._execute(), self.model_class)
	  File "/usr/local/lib/python2.7/dist-packages/peewee.py", line 1671, in _execute
	    return self.database.execute_sql(sql, params, self.require_commit)
	  File "/usr/local/lib/python2.7/dist-packages/peewee.py", line 2162, in execute_sql
	    self.commit()
	  File "/usr/local/lib/python2.7/dist-packages/peewee.py", line 2036, in __exit__
	    reraise(new_type, new_type(*exc_value.args), traceback)
	  File "/usr/local/lib/python2.7/dist-packages/peewee.py", line 2153, in execute_sql
	    res = cursor.execute(sql, params or ())
	peewee.InternalError: current transaction is aborted, commands ignored until end of transaction block
	
	
2014-02-10 16:15:29+0800 [taobao] ERROR: Error processing {'commId': 35097573089L,
	 'flag': 'Commodity',
	 'rateNumber': 460,
	 'sellerId': 280003475,
	 'title': u'Apple/\u82f9\u679c iPhone 5S \u82f9\u679c5S \u6e2f\u7248\u539f\u5c01\u672a\u6fc0\u6d3b \u4e09\u7f51\u7248\u7535\u4fe1 \u9a6c\u4e0a\u53d1',
	 'turnover': 199}
	Traceback (most recent call last):
	  File "/usr/local/lib/python2.7/dist-packages/scrapy/middleware.py", line 62, in _process_chain
	    return process_chain(self.methods[methodname], obj, *args)
	  File "/usr/local/lib/python2.7/dist-packages/scrapy/utils/defer.py", line 65, in process_chain
	    d.callback(input)
	  File "/usr/local/lib/python2.7/dist-packages/twisted/internet/defer.py", line 382, in callback
	    self._startRunCallbacks(result)
	  File "/usr/local/lib/python2.7/dist-packages/twisted/internet/defer.py", line 490, in _startRunCallbacks
	    self._runCallbacks()
	--- <exception caught here> ---
	  File "/usr/local/lib/python2.7/dist-packages/twisted/internet/defer.py", line 577, in _runCallbacks
	    current.result = callback(current.result, *args, **kw)
	  File "/home/zq/Project/taobao/taobao/pipelines.py", line 30, in process_item
	    commodity.save()
	  File "/usr/local/lib/python2.7/dist-packages/peewee.py", line 2837, in save
	    ret_pk = self.insert(**field_dict).execute()
	  File "/usr/local/lib/python2.7/dist-packages/peewee.py", line 2000, in execute
	    return self.database.last_insert_id(self._execute(), self.model_class)
	  File "/usr/local/lib/python2.7/dist-packages/peewee.py", line 1671, in _execute
	    return self.database.execute_sql(sql, params, self.require_commit)
	  File "/usr/local/lib/python2.7/dist-packages/peewee.py", line 2162, in execute_sql
	    self.commit()
	  File "/usr/local/lib/python2.7/dist-packages/peewee.py", line 2036, in __exit__
	    reraise(new_type, new_type(*exc_value.args), traceback)
	  File "/usr/local/lib/python2.7/dist-packages/peewee.py", line 2153, in execute_sql
	    res = cursor.execute(sql, params or ())
	peewee.InternalError: current transaction is aborted, commands ignored until end of transaction block
	
	
2014-02-10 16:15:29+0800 [taobao] ERROR: Error processing {'commId': 36282039921L,
	 'flag': 'Commodity',
	 'rateNumber': 416,
	 'sellerId': 37213332,
	 'title': u'Apple/\u82f9\u679c iPhone 5S \u82f9\u679c5S 16G 32G \u4e24\u7f51\u4e09\u7f51\u7535\u4fe1\u6b63\u54c1\u65e0\u9501\u73b0\u8d27',
	 'turnover': 560}
	Traceback (most recent call last):
	  File "/usr/local/lib/python2.7/dist-packages/scrapy/middleware.py", line 62, in _process_chain
	    return process_chain(self.methods[methodname], obj, *args)
	  File "/usr/local/lib/python2.7/dist-packages/scrapy/utils/defer.py", line 65, in process_chain
	    d.callback(input)
	  File "/usr/local/lib/python2.7/dist-packages/twisted/internet/defer.py", line 382, in callback
	    self._startRunCallbacks(result)
	  File "/usr/local/lib/python2.7/dist-packages/twisted/internet/defer.py", line 490, in _startRunCallbacks
	    self._runCallbacks()
	--- <exception caught here> ---
	  File "/usr/local/lib/python2.7/dist-packages/twisted/internet/defer.py", line 577, in _runCallbacks
	    current.result = callback(current.result, *args, **kw)
	  File "/home/zq/Project/taobao/taobao/pipelines.py", line 30, in process_item
	    commodity.save()
	  File "/usr/local/lib/python2.7/dist-packages/peewee.py", line 2837, in save
	    ret_pk = self.insert(**field_dict).execute()
	  File "/usr/local/lib/python2.7/dist-packages/peewee.py", line 2000, in execute
	    return self.database.last_insert_id(self._execute(), self.model_class)
	  File "/usr/local/lib/python2.7/dist-packages/peewee.py", line 1671, in _execute
	    return self.database.execute_sql(sql, params, self.require_commit)
	  File "/usr/local/lib/python2.7/dist-packages/peewee.py", line 2162, in execute_sql
	    self.commit()
	  File "/usr/local/lib/python2.7/dist-packages/peewee.py", line 2036, in __exit__
	    reraise(new_type, new_type(*exc_value.args), traceback)
	  File "/usr/local/lib/python2.7/dist-packages/peewee.py", line 2153, in execute_sql
	    res = cursor.execute(sql, params or ())
	peewee.InternalError: current transaction is aborted, commands ignored until end of transaction block
	
	
2014-02-10 16:15:29+0800 [taobao] ERROR: Error processing {'commId': 35567022349L,
	 'flag': 'Commodity',
	 'rateNumber': 430,
	 'sellerId': 470823318,
	 'title': u'Apple/\u82f9\u679c iPhone 5s \uff08\u6709\u9501\uff09\u65e5\u7248 \u7f8e\u7248ATT \u4e24\u7f51 \u6709\u539f\u5c01\u672a\u6fc0\u6d3b',
	 'turnover': 455}
	Traceback (most recent call last):
	  File "/usr/local/lib/python2.7/dist-packages/scrapy/middleware.py", line 62, in _process_chain
	    return process_chain(self.methods[methodname], obj, *args)
	  File "/usr/local/lib/python2.7/dist-packages/scrapy/utils/defer.py", line 65, in process_chain
	    d.callback(input)
	  File "/usr/local/lib/python2.7/dist-packages/twisted/internet/defer.py", line 382, in callback
	    self._startRunCallbacks(result)
	  File "/usr/local/lib/python2.7/dist-packages/twisted/internet/defer.py", line 490, in _startRunCallbacks
	    self._runCallbacks()
	--- <exception caught here> ---
	  File "/usr/local/lib/python2.7/dist-packages/twisted/internet/defer.py", line 577, in _runCallbacks
	    current.result = callback(current.result, *args, **kw)
	  File "/home/zq/Project/taobao/taobao/pipelines.py", line 30, in process_item
	    commodity.save()
	  File "/usr/local/lib/python2.7/dist-packages/peewee.py", line 2837, in save
	    ret_pk = self.insert(**field_dict).execute()
	  File "/usr/local/lib/python2.7/dist-packages/peewee.py", line 2000, in execute
	    return self.database.last_insert_id(self._execute(), self.model_class)
	  File "/usr/local/lib/python2.7/dist-packages/peewee.py", line 1671, in _execute
	    return self.database.execute_sql(sql, params, self.require_commit)
	  File "/usr/local/lib/python2.7/dist-packages/peewee.py", line 2162, in execute_sql
	    self.commit()
	  File "/usr/local/lib/python2.7/dist-packages/peewee.py", line 2036, in __exit__
	    reraise(new_type, new_type(*exc_value.args), traceback)
	  File "/usr/local/lib/python2.7/dist-packages/peewee.py", line 2153, in execute_sql
	    res = cursor.execute(sql, params or ())
	peewee.InternalError: current transaction is aborted, commands ignored until end of transaction block
	
	
2014-02-10 16:15:29+0800 [taobao] ERROR: Error processing {'commId': 20308334886L,
	 'flag': 'Commodity',
	 'rateNumber': 432,
	 'sellerId': 48788909,
	 'title': u'\u7a46\u4e30\u25c6Apple/\u82f9\u679c iPhone 5S \u672a\u6fc0\u6d3b iPhone5s \u79fb\u52a84G\u571f\u8c6a\u91d1A1530',
	 'turnover': 561}
	Traceback (most recent call last):
	  File "/usr/local/lib/python2.7/dist-packages/scrapy/middleware.py", line 62, in _process_chain
	    return process_chain(self.methods[methodname], obj, *args)
	  File "/usr/local/lib/python2.7/dist-packages/scrapy/utils/defer.py", line 65, in process_chain
	    d.callback(input)
	  File "/usr/local/lib/python2.7/dist-packages/twisted/internet/defer.py", line 382, in callback
	    self._startRunCallbacks(result)
	  File "/usr/local/lib/python2.7/dist-packages/twisted/internet/defer.py", line 490, in _startRunCallbacks
	    self._runCallbacks()
	--- <exception caught here> ---
	  File "/usr/local/lib/python2.7/dist-packages/twisted/internet/defer.py", line 577, in _runCallbacks
	    current.result = callback(current.result, *args, **kw)
	  File "/home/zq/Project/taobao/taobao/pipelines.py", line 30, in process_item
	    commodity.save()
	  File "/usr/local/lib/python2.7/dist-packages/peewee.py", line 2837, in save
	    ret_pk = self.insert(**field_dict).execute()
	  File "/usr/local/lib/python2.7/dist-packages/peewee.py", line 2000, in execute
	    return self.database.last_insert_id(self._execute(), self.model_class)
	  File "/usr/local/lib/python2.7/dist-packages/peewee.py", line 1671, in _execute
	    return self.database.execute_sql(sql, params, self.require_commit)
	  File "/usr/local/lib/python2.7/dist-packages/peewee.py", line 2162, in execute_sql
	    self.commit()
	  File "/usr/local/lib/python2.7/dist-packages/peewee.py", line 2036, in __exit__
	    reraise(new_type, new_type(*exc_value.args), traceback)
	  File "/usr/local/lib/python2.7/dist-packages/peewee.py", line 2153, in execute_sql
	    res = cursor.execute(sql, params or ())
	peewee.InternalError: current transaction is aborted, commands ignored until end of transaction block
	
	
2014-02-10 16:15:29+0800 [taobao] ERROR: Error processing {'commId': 35251170624L,
	 'flag': 'Commodity',
	 'rateNumber': 1439,
	 'sellerId': 214498135,
	 'title': u'\u5047\u4e00\u8d54\u4e07Apple/\u82f9\u679c iPhone 5s \u82f9\u679c5S\u624b\u673a \u65e5\u7248 \u7f8e\u7248 \u7ea2\u5305\u8fce\u65b0\u5e74',
	 'turnover': 555}
	Traceback (most recent call last):
	  File "/usr/local/lib/python2.7/dist-packages/scrapy/middleware.py", line 62, in _process_chain
	    return process_chain(self.methods[methodname], obj, *args)
	  File "/usr/local/lib/python2.7/dist-packages/scrapy/utils/defer.py", line 65, in process_chain
	    d.callback(input)
	  File "/usr/local/lib/python2.7/dist-packages/twisted/internet/defer.py", line 382, in callback
	    self._startRunCallbacks(result)
	  File "/usr/local/lib/python2.7/dist-packages/twisted/internet/defer.py", line 490, in _startRunCallbacks
	    self._runCallbacks()
	--- <exception caught here> ---
	  File "/usr/local/lib/python2.7/dist-packages/twisted/internet/defer.py", line 577, in _runCallbacks
	    current.result = callback(current.result, *args, **kw)
	  File "/home/zq/Project/taobao/taobao/pipelines.py", line 30, in process_item
	    commodity.save()
	  File "/usr/local/lib/python2.7/dist-packages/peewee.py", line 2837, in save
	    ret_pk = self.insert(**field_dict).execute()
	  File "/usr/local/lib/python2.7/dist-packages/peewee.py", line 2000, in execute
	    return self.database.last_insert_id(self._execute(), self.model_class)
	  File "/usr/local/lib/python2.7/dist-packages/peewee.py", line 1671, in _execute
	    return self.database.execute_sql(sql, params, self.require_commit)
	  File "/usr/local/lib/python2.7/dist-packages/peewee.py", line 2162, in execute_sql
	    self.commit()
	  File "/usr/local/lib/python2.7/dist-packages/peewee.py", line 2036, in __exit__
	    reraise(new_type, new_type(*exc_value.args), traceback)
	  File "/usr/local/lib/python2.7/dist-packages/peewee.py", line 2153, in execute_sql
	    res = cursor.execute(sql, params or ())
	peewee.InternalError: current transaction is aborted, commands ignored until end of transaction block
	
	
2014-02-10 16:15:29+0800 [taobao] ERROR: Error processing {'commId': 20099094566L,
	 'flag': 'Commodity',
	 'rateNumber': 2478,
	 'sellerId': 898225,
	 'title': u'[\u539f\u5c01\u672a\u6fc0\u6d3b \u571f\u8c6a\u91d14188]Apple/\u82f9\u679c iPhone 5S\u82f9\u679c5S\u4e09\u7f51V\u7248\u6e2f\u7248',
	 'turnover': 1092}
	Traceback (most recent call last):
	  File "/usr/local/lib/python2.7/dist-packages/scrapy/middleware.py", line 62, in _process_chain
	    return process_chain(self.methods[methodname], obj, *args)
	  File "/usr/local/lib/python2.7/dist-packages/scrapy/utils/defer.py", line 65, in process_chain
	    d.callback(input)
	  File "/usr/local/lib/python2.7/dist-packages/twisted/internet/defer.py", line 382, in callback
	    self._startRunCallbacks(result)
	  File "/usr/local/lib/python2.7/dist-packages/twisted/internet/defer.py", line 490, in _startRunCallbacks
	    self._runCallbacks()
	--- <exception caught here> ---
	  File "/usr/local/lib/python2.7/dist-packages/twisted/internet/defer.py", line 577, in _runCallbacks
	    current.result = callback(current.result, *args, **kw)
	  File "/home/zq/Project/taobao/taobao/pipelines.py", line 30, in process_item
	    commodity.save()
	  File "/usr/local/lib/python2.7/dist-packages/peewee.py", line 2837, in save
	    ret_pk = self.insert(**field_dict).execute()
	  File "/usr/local/lib/python2.7/dist-packages/peewee.py", line 2000, in execute
	    return self.database.last_insert_id(self._execute(), self.model_class)
	  File "/usr/local/lib/python2.7/dist-packages/peewee.py", line 1671, in _execute
	    return self.database.execute_sql(sql, params, self.require_commit)
	  File "/usr/local/lib/python2.7/dist-packages/peewee.py", line 2162, in execute_sql
	    self.commit()
	  File "/usr/local/lib/python2.7/dist-packages/peewee.py", line 2036, in __exit__
	    reraise(new_type, new_type(*exc_value.args), traceback)
	  File "/usr/local/lib/python2.7/dist-packages/peewee.py", line 2153, in execute_sql
	    res = cursor.execute(sql, params or ())
	peewee.InternalError: current transaction is aborted, commands ignored until end of transaction block
	
	
2014-02-10 16:15:29+0800 [taobao] ERROR: Error processing {'commId': 20144697863L,
	 'flag': 'Commodity',
	 'rateNumber': 698,
	 'sellerId': 129307262,
	 'title': u'\u65b0\u5e74\u7279\u4ef7Apple/\u82f9\u679c iPhone 5S \u56fd\u884c/\u6e2f\u7248A1530\u652f\u6301\u79fb\u52a84G\u5305\u90ae',
	 'turnover': 741}
	Traceback (most recent call last):
	  File "/usr/local/lib/python2.7/dist-packages/scrapy/middleware.py", line 62, in _process_chain
	    return process_chain(self.methods[methodname], obj, *args)
	  File "/usr/local/lib/python2.7/dist-packages/scrapy/utils/defer.py", line 65, in process_chain
	    d.callback(input)
	  File "/usr/local/lib/python2.7/dist-packages/twisted/internet/defer.py", line 382, in callback
	    self._startRunCallbacks(result)
	  File "/usr/local/lib/python2.7/dist-packages/twisted/internet/defer.py", line 490, in _startRunCallbacks
	    self._runCallbacks()
	--- <exception caught here> ---
	  File "/usr/local/lib/python2.7/dist-packages/twisted/internet/defer.py", line 577, in _runCallbacks
	    current.result = callback(current.result, *args, **kw)
	  File "/home/zq/Project/taobao/taobao/pipelines.py", line 30, in process_item
	    commodity.save()
	  File "/usr/local/lib/python2.7/dist-packages/peewee.py", line 2837, in save
	    ret_pk = self.insert(**field_dict).execute()
	  File "/usr/local/lib/python2.7/dist-packages/peewee.py", line 2000, in execute
	    return self.database.last_insert_id(self._execute(), self.model_class)
	  File "/usr/local/lib/python2.7/dist-packages/peewee.py", line 1671, in _execute
	    return self.database.execute_sql(sql, params, self.require_commit)
	  File "/usr/local/lib/python2.7/dist-packages/peewee.py", line 2162, in execute_sql
	    self.commit()
	  File "/usr/local/lib/python2.7/dist-packages/peewee.py", line 2036, in __exit__
	    reraise(new_type, new_type(*exc_value.args), traceback)
	  File "/usr/local/lib/python2.7/dist-packages/peewee.py", line 2153, in execute_sql
	    res = cursor.execute(sql, params or ())
	peewee.InternalError: current transaction is aborted, commands ignored until end of transaction block
	
	
2014-02-10 16:15:29+0800 [taobao] ERROR: Error processing {'commId': 20207569618L,
	 'flag': 'Commodity',
	 'rateNumber': 1319,
	 'sellerId': 441017263,
	 'title': u'\u3010\u6b63\u5f0f\u4e0a\u73ed \u5f53\u5929\u53d1\u8d27\u3011Apple/\u82f9\u679c iPhone 5S v\u7248 \u4e09\u7f51 \u7535\u4fe1 \u6e2f\u7248',
	 'turnover': 789}
	Traceback (most recent call last):
	  File "/usr/local/lib/python2.7/dist-packages/scrapy/middleware.py", line 62, in _process_chain
	    return process_chain(self.methods[methodname], obj, *args)
	  File "/usr/local/lib/python2.7/dist-packages/scrapy/utils/defer.py", line 65, in process_chain
	    d.callback(input)
	  File "/usr/local/lib/python2.7/dist-packages/twisted/internet/defer.py", line 382, in callback
	    self._startRunCallbacks(result)
	  File "/usr/local/lib/python2.7/dist-packages/twisted/internet/defer.py", line 490, in _startRunCallbacks
	    self._runCallbacks()
	--- <exception caught here> ---
	  File "/usr/local/lib/python2.7/dist-packages/twisted/internet/defer.py", line 577, in _runCallbacks
	    current.result = callback(current.result, *args, **kw)
	  File "/home/zq/Project/taobao/taobao/pipelines.py", line 30, in process_item
	    commodity.save()
	  File "/usr/local/lib/python2.7/dist-packages/peewee.py", line 2837, in save
	    ret_pk = self.insert(**field_dict).execute()
	  File "/usr/local/lib/python2.7/dist-packages/peewee.py", line 2000, in execute
	    return self.database.last_insert_id(self._execute(), self.model_class)
	  File "/usr/local/lib/python2.7/dist-packages/peewee.py", line 1671, in _execute
	    return self.database.execute_sql(sql, params, self.require_commit)
	  File "/usr/local/lib/python2.7/dist-packages/peewee.py", line 2162, in execute_sql
	    self.commit()
	  File "/usr/local/lib/python2.7/dist-packages/peewee.py", line 2036, in __exit__
	    reraise(new_type, new_type(*exc_value.args), traceback)
	  File "/usr/local/lib/python2.7/dist-packages/peewee.py", line 2153, in execute_sql
	    res = cursor.execute(sql, params or ())
	peewee.InternalError: current transaction is aborted, commands ignored until end of transaction block
	
	
2014-02-10 16:15:29+0800 [taobao] ERROR: Error processing {'commId': 20024530272L,
	 'flag': 'Commodity',
	 'rateNumber': 1299,
	 'sellerId': 71011031,
	 'title': u'Apple/\u82f9\u679c iPhone 5S \u9999\u6e2f\u5546\u5bb6 \u539f\u5c01\u672a\u6fc0\u6d3b\u5305\u90ae \u767e\u5206\u767e\u539f\u88c5 \u72c2\u4fc3',
	 'turnover': 635}
	Traceback (most recent call last):
	  File "/usr/local/lib/python2.7/dist-packages/scrapy/middleware.py", line 62, in _process_chain
	    return process_chain(self.methods[methodname], obj, *args)
	  File "/usr/local/lib/python2.7/dist-packages/scrapy/utils/defer.py", line 65, in process_chain
	    d.callback(input)
	  File "/usr/local/lib/python2.7/dist-packages/twisted/internet/defer.py", line 382, in callback
	    self._startRunCallbacks(result)
	  File "/usr/local/lib/python2.7/dist-packages/twisted/internet/defer.py", line 490, in _startRunCallbacks
	    self._runCallbacks()
	--- <exception caught here> ---
	  File "/usr/local/lib/python2.7/dist-packages/twisted/internet/defer.py", line 577, in _runCallbacks
	    current.result = callback(current.result, *args, **kw)
	  File "/home/zq/Project/taobao/taobao/pipelines.py", line 30, in process_item
	    commodity.save()
	  File "/usr/local/lib/python2.7/dist-packages/peewee.py", line 2837, in save
	    ret_pk = self.insert(**field_dict).execute()
	  File "/usr/local/lib/python2.7/dist-packages/peewee.py", line 2000, in execute
	    return self.database.last_insert_id(self._execute(), self.model_class)
	  File "/usr/local/lib/python2.7/dist-packages/peewee.py", line 1671, in _execute
	    return self.database.execute_sql(sql, params, self.require_commit)
	  File "/usr/local/lib/python2.7/dist-packages/peewee.py", line 2162, in execute_sql
	    self.commit()
	  File "/usr/local/lib/python2.7/dist-packages/peewee.py", line 2036, in __exit__
	    reraise(new_type, new_type(*exc_value.args), traceback)
	  File "/usr/local/lib/python2.7/dist-packages/peewee.py", line 2153, in execute_sql
	    res = cursor.execute(sql, params or ())
	peewee.InternalError: current transaction is aborted, commands ignored until end of transaction block
	
	
2014-02-10 16:15:29+0800 [taobao] ERROR: Error processing {'commId': 36157528669L,
	 'flag': 'Commodity',
	 'rateNumber': 224,
	 'sellerId': 325959470,
	 'title': u'\u3010\u6709\u539f\u5c01\u672a\u6fc0\u6d3b\u3011 Apple/\u82f9\u679c iPhone 5s(\u6709\u9501)  \u65e5\u7248\u7f8e\u7248 \u9001\u7ea2\u5305',
	 'turnover': 337}
	Traceback (most recent call last):
	  File "/usr/local/lib/python2.7/dist-packages/scrapy/middleware.py", line 62, in _process_chain
	    return process_chain(self.methods[methodname], obj, *args)
	  File "/usr/local/lib/python2.7/dist-packages/scrapy/utils/defer.py", line 65, in process_chain
	    d.callback(input)
	  File "/usr/local/lib/python2.7/dist-packages/twisted/internet/defer.py", line 382, in callback
	    self._startRunCallbacks(result)
	  File "/usr/local/lib/python2.7/dist-packages/twisted/internet/defer.py", line 490, in _startRunCallbacks
	    self._runCallbacks()
	--- <exception caught here> ---
	  File "/usr/local/lib/python2.7/dist-packages/twisted/internet/defer.py", line 577, in _runCallbacks
	    current.result = callback(current.result, *args, **kw)
	  File "/home/zq/Project/taobao/taobao/pipelines.py", line 30, in process_item
	    commodity.save()
	  File "/usr/local/lib/python2.7/dist-packages/peewee.py", line 2837, in save
	    ret_pk = self.insert(**field_dict).execute()
	  File "/usr/local/lib/python2.7/dist-packages/peewee.py", line 2000, in execute
	    return self.database.last_insert_id(self._execute(), self.model_class)
	  File "/usr/local/lib/python2.7/dist-packages/peewee.py", line 1671, in _execute
	    return self.database.execute_sql(sql, params, self.require_commit)
	  File "/usr/local/lib/python2.7/dist-packages/peewee.py", line 2162, in execute_sql
	    self.commit()
	  File "/usr/local/lib/python2.7/dist-packages/peewee.py", line 2036, in __exit__
	    reraise(new_type, new_type(*exc_value.args), traceback)
	  File "/usr/local/lib/python2.7/dist-packages/peewee.py", line 2153, in execute_sql
	    res = cursor.execute(sql, params or ())
	peewee.InternalError: current transaction is aborted, commands ignored until end of transaction block
	
	
2014-02-10 16:15:29+0800 [taobao] ERROR: Error processing {'commId': 20100593439L,
	 'flag': 'Commodity',
	 'rateNumber': 1252,
	 'sellerId': 70296483,
	 'title': u'Apple/\u82f9\u679c iPhone 5S\u91d1\u8272\u539f\u5c01\u5c0f\u7968\u3010\u652f\u6301\u9a8c\u8d27\u6e2f\u7248\u91d1\u82724418\u73b0\u53d1\u3011',
	 'turnover': 445}
	Traceback (most recent call last):
	  File "/usr/local/lib/python2.7/dist-packages/scrapy/middleware.py", line 62, in _process_chain
	    return process_chain(self.methods[methodname], obj, *args)
	  File "/usr/local/lib/python2.7/dist-packages/scrapy/utils/defer.py", line 65, in process_chain
	    d.callback(input)
	  File "/usr/local/lib/python2.7/dist-packages/twisted/internet/defer.py", line 382, in callback
	    self._startRunCallbacks(result)
	  File "/usr/local/lib/python2.7/dist-packages/twisted/internet/defer.py", line 490, in _startRunCallbacks
	    self._runCallbacks()
	--- <exception caught here> ---
	  File "/usr/local/lib/python2.7/dist-packages/twisted/internet/defer.py", line 577, in _runCallbacks
	    current.result = callback(current.result, *args, **kw)
	  File "/home/zq/Project/taobao/taobao/pipelines.py", line 30, in process_item
	    commodity.save()
	  File "/usr/local/lib/python2.7/dist-packages/peewee.py", line 2837, in save
	    ret_pk = self.insert(**field_dict).execute()
	  File "/usr/local/lib/python2.7/dist-packages/peewee.py", line 2000, in execute
	    return self.database.last_insert_id(self._execute(), self.model_class)
	  File "/usr/local/lib/python2.7/dist-packages/peewee.py", line 1671, in _execute
	    return self.database.execute_sql(sql, params, self.require_commit)
	  File "/usr/local/lib/python2.7/dist-packages/peewee.py", line 2162, in execute_sql
	    self.commit()
	  File "/usr/local/lib/python2.7/dist-packages/peewee.py", line 2036, in __exit__
	    reraise(new_type, new_type(*exc_value.args), traceback)
	  File "/usr/local/lib/python2.7/dist-packages/peewee.py", line 2153, in execute_sql
	    res = cursor.execute(sql, params or ())
	peewee.InternalError: current transaction is aborted, commands ignored until end of transaction block
	
	
2014-02-10 16:15:29+0800 [taobao] ERROR: Error processing {'commId': 27503360785L,
	 'flag': 'Commodity',
	 'rateNumber': 248,
	 'sellerId': 101209807,
	 'title': u'Apple/\u82f9\u679c iPhone 5s(\u6709\u9501)   iphone 5S \u65e5\u7248 \u7f8e\u7248\u539f\u5c01\u672a\u6fc0\u6d3b',
	 'turnover': 197}
	Traceback (most recent call last):
	  File "/usr/local/lib/python2.7/dist-packages/scrapy/middleware.py", line 62, in _process_chain
	    return process_chain(self.methods[methodname], obj, *args)
	  File "/usr/local/lib/python2.7/dist-packages/scrapy/utils/defer.py", line 65, in process_chain
	    d.callback(input)
	  File "/usr/local/lib/python2.7/dist-packages/twisted/internet/defer.py", line 382, in callback
	    self._startRunCallbacks(result)
	  File "/usr/local/lib/python2.7/dist-packages/twisted/internet/defer.py", line 490, in _startRunCallbacks
	    self._runCallbacks()
	--- <exception caught here> ---
	  File "/usr/local/lib/python2.7/dist-packages/twisted/internet/defer.py", line 577, in _runCallbacks
	    current.result = callback(current.result, *args, **kw)
	  File "/home/zq/Project/taobao/taobao/pipelines.py", line 30, in process_item
	    commodity.save()
	  File "/usr/local/lib/python2.7/dist-packages/peewee.py", line 2837, in save
	    ret_pk = self.insert(**field_dict).execute()
	  File "/usr/local/lib/python2.7/dist-packages/peewee.py", line 2000, in execute
	    return self.database.last_insert_id(self._execute(), self.model_class)
	  File "/usr/local/lib/python2.7/dist-packages/peewee.py", line 1671, in _execute
	    return self.database.execute_sql(sql, params, self.require_commit)
	  File "/usr/local/lib/python2.7/dist-packages/peewee.py", line 2162, in execute_sql
	    self.commit()
	  File "/usr/local/lib/python2.7/dist-packages/peewee.py", line 2036, in __exit__
	    reraise(new_type, new_type(*exc_value.args), traceback)
	  File "/usr/local/lib/python2.7/dist-packages/peewee.py", line 2153, in execute_sql
	    res = cursor.execute(sql, params or ())
	peewee.InternalError: current transaction is aborted, commands ignored until end of transaction block
	
	
2014-02-10 16:15:29+0800 [taobao] ERROR: Error processing {'commId': 35832343555L,
	 'flag': 'Commodity',
	 'rateNumber': 75,
	 'sellerId': 94092456,
	 'title': u'\u65b0\u5e74\u4fc3\u9500Apple/\u82f9\u679c iPhone 5 \u7f8e\u7248\u4e09\u7f51 \u6e2f\u7248 \u539f\u751f\u65e0\u9501 \u73b0\u8d27\u5305\u90ae',
	 'turnover': 249}
	Traceback (most recent call last):
	  File "/usr/local/lib/python2.7/dist-packages/scrapy/middleware.py", line 62, in _process_chain
	    return process_chain(self.methods[methodname], obj, *args)
	  File "/usr/local/lib/python2.7/dist-packages/scrapy/utils/defer.py", line 65, in process_chain
	    d.callback(input)
	  File "/usr/local/lib/python2.7/dist-packages/twisted/internet/defer.py", line 382, in callback
	    self._startRunCallbacks(result)
	  File "/usr/local/lib/python2.7/dist-packages/twisted/internet/defer.py", line 490, in _startRunCallbacks
	    self._runCallbacks()
	--- <exception caught here> ---
	  File "/usr/local/lib/python2.7/dist-packages/twisted/internet/defer.py", line 577, in _runCallbacks
	    current.result = callback(current.result, *args, **kw)
	  File "/home/zq/Project/taobao/taobao/pipelines.py", line 30, in process_item
	    commodity.save()
	  File "/usr/local/lib/python2.7/dist-packages/peewee.py", line 2837, in save
	    ret_pk = self.insert(**field_dict).execute()
	  File "/usr/local/lib/python2.7/dist-packages/peewee.py", line 2000, in execute
	    return self.database.last_insert_id(self._execute(), self.model_class)
	  File "/usr/local/lib/python2.7/dist-packages/peewee.py", line 1671, in _execute
	    return self.database.execute_sql(sql, params, self.require_commit)
	  File "/usr/local/lib/python2.7/dist-packages/peewee.py", line 2162, in execute_sql
	    self.commit()
	  File "/usr/local/lib/python2.7/dist-packages/peewee.py", line 2036, in __exit__
	    reraise(new_type, new_type(*exc_value.args), traceback)
	  File "/usr/local/lib/python2.7/dist-packages/peewee.py", line 2153, in execute_sql
	    res = cursor.execute(sql, params or ())
	peewee.InternalError: current transaction is aborted, commands ignored until end of transaction block
	
	
2014-02-10 16:15:29+0800 [taobao] ERROR: Error processing {'commId': 36156905254L,
	 'flag': 'Commodity',
	 'rateNumber': 95,
	 'sellerId': 761145597,
	 'title': u'Apple/\u82f9\u679c iPhone 5s \u82f9\u679c5S \u539f\u88c5\u6b63\u54c1 \u571f\u8c6a\u91d1 \u6709\u672a\u6fc0\u6d3b \u8fce\u65b0\u5e74',
	 'turnover': 20}
	Traceback (most recent call last):
	  File "/usr/local/lib/python2.7/dist-packages/scrapy/middleware.py", line 62, in _process_chain
	    return process_chain(self.methods[methodname], obj, *args)
	  File "/usr/local/lib/python2.7/dist-packages/scrapy/utils/defer.py", line 65, in process_chain
	    d.callback(input)
	  File "/usr/local/lib/python2.7/dist-packages/twisted/internet/defer.py", line 382, in callback
	    self._startRunCallbacks(result)
	  File "/usr/local/lib/python2.7/dist-packages/twisted/internet/defer.py", line 490, in _startRunCallbacks
	    self._runCallbacks()
	--- <exception caught here> ---
	  File "/usr/local/lib/python2.7/dist-packages/twisted/internet/defer.py", line 577, in _runCallbacks
	    current.result = callback(current.result, *args, **kw)
	  File "/home/zq/Project/taobao/taobao/pipelines.py", line 30, in process_item
	    commodity.save()
	  File "/usr/local/lib/python2.7/dist-packages/peewee.py", line 2837, in save
	    ret_pk = self.insert(**field_dict).execute()
	  File "/usr/local/lib/python2.7/dist-packages/peewee.py", line 2000, in execute
	    return self.database.last_insert_id(self._execute(), self.model_class)
	  File "/usr/local/lib/python2.7/dist-packages/peewee.py", line 1671, in _execute
	    return self.database.execute_sql(sql, params, self.require_commit)
	  File "/usr/local/lib/python2.7/dist-packages/peewee.py", line 2162, in execute_sql
	    self.commit()
	  File "/usr/local/lib/python2.7/dist-packages/peewee.py", line 2036, in __exit__
	    reraise(new_type, new_type(*exc_value.args), traceback)
	  File "/usr/local/lib/python2.7/dist-packages/peewee.py", line 2153, in execute_sql
	    res = cursor.execute(sql, params or ())
	peewee.InternalError: current transaction is aborted, commands ignored until end of transaction block
	
	
2014-02-10 16:15:29+0800 [taobao] INFO: Closing spider (finished)
2014-02-10 16:15:29+0800 [taobao] INFO: Dumping Scrapy stats:
	{'downloader/request_bytes': 573,
	 'downloader/request_count': 2,
	 'downloader/request_method_count/GET': 2,
	 'downloader/response_bytes': 43588,
	 'downloader/response_count': 2,
	 'downloader/response_status_count/200': 2,
	 'finish_reason': 'finished',
	 'finish_time': datetime.datetime(2014, 2, 10, 8, 15, 29, 639804),
	 'log_count/DEBUG': 4,
	 'log_count/ERROR': 54,
	 'log_count/INFO': 7,
	 'request_depth_max': 1,
	 'response_received_count': 2,
	 'scheduler/dequeued': 2,
	 'scheduler/dequeued/memory': 2,
	 'scheduler/enqueued': 2,
	 'scheduler/enqueued/memory': 2,
	 'start_time': datetime.datetime(2014, 2, 10, 8, 15, 28, 756936)}
2014-02-10 16:15:29+0800 [taobao] INFO: Spider closed (finished)
